Workbook

Sheet Character
A1: WARHAMMER FANTASY ROLEPLAY 5E — CHARACTER
A2: White cells: enter values · Grey cells: calculated · Yellow: starting (free) advances · Dropdowns accept custom text (a warning is shown).
A3: Name | F3: Species | M3: Career
A4: Career level | F4: Career title | H4: =IF(OR($O$3="",$B$4=""),"",IFERROR(INDEX(Data_Careers!$E:$E,MATCH($O$3&"|"&$B$4,Data_Careers!$A:$A,0)),"")) | M4: Class | O4: =IF($O$3="","",IFERROR(INDEX(Data_Careers!$D:$D,MATCH($O$3&"|1",Data_Careers!$A:$A,0)),""))
A5: Status | B5: =IF(OR($O$3="",$B$4=""),"",IFERROR(INDEX(Data_Careers!$F:$F,MATCH($O$3&"|"&$B$4,Data_Careers!$A:$A,0)),"")) | F5: Income skill | H5: =IF($O$3="","",IFERROR(INDEX(Data_Careers!$M:$M,MATCH($O$3&"|1",Data_Careers!$A:$A,0)),"")) | M5: Age
A6: Height | F6: Eyes | M6: Hair
A7: Ambition | M7: Party ambition
A9: CHARACTERISTICS | M9: ATTRIBUTES
B10: WS | C10: BS | D10: S | E10: T | F10: I | G10: Ag | H10: Dex | I10: Int | J10: WP | K10: Fel | O10: Current | P10: Max | Q10: How it is calculated
A11: Initial (species + roll + career pts) | M11: Wounds | P11: =$D$17+$J$17+2*$E$17+$E$17*SUMIF($M$27:$M$77,"Hardy",$U$27:$U$77) | Q11: SB + WPB + 2×TB (+TB per Hardy)
A12: Advances (+5 each) | B12: 0 | C12: 0 | D12: 0 | E12: 0 | F12: 0 | G12: 0 | H12: 0 | I12: 0 | J12: 0 | K12: 0 | M12: Fate | P12: =IF($H$3="","",IFERROR(INDEX(Data_Lists!$B$2:$B$6,MATCH($H$3,Data_Lists!$A$2:$A$6,0)),"")) | Q12: Species Fate (+1 if you kept all first rolls)
A13: …of which non-career | B13: 0 | C13: 0 | D13: 0 | E13: 0 | F13: 0 | G13: 0 | H13: 0 | I13: 0 | J13: 0 | K13: 0 | M13: Fortune | P13: =IF($H$3="","",IFERROR(INDEX(Data_Lists!$C$2:$C$6,MATCH($H$3,Data_Lists!$A$2:$A$6,0)),"")+MIN(3,SUMIF($M$27:$M$77,"Luck",$U$27:$U$77))) | Q13: Species Fortune (+1 if you kept the species roll) + Luck
A14: Talent bonus (auto) | B14: =5*SUMIF($T$27:$T$77,B$10,$U$27:$U$77) | C14: =5*SUMIF($T$27:$T$77,C$10,$U$27:$U$77) | D14: =5*SUMIF($T$27:$T$77,D$10,$U$27:$U$77) | E14: =5*SUMIF($T$27:$T$77,E$10,$U$27:$U$77) | F14: =5*SUMIF($T$27:$T$77,F$10,$U$27:$U$77) | G14: =5*SUMIF($T$27:$T$77,G$10,$U$27:$U$77) | H14: =5*SUMIF($T$27:$T$77,H$10,$U$27:$U$77) | I14: =5*SUMIF($T$27:$T$77,I$10,$U$27:$U$77) | ... K14: =5*SUMIF($T$27:$T$77,K$10,$U$27:$U$77) | M14: Movement | O14: =IF($H$3="","",IFERROR(INDEX(Data_Lists!$D$2:$D$6,MATCH($H$3,Data_Lists!$A$2:$A$6,0)),"")+IF(SUMIF($M$27:$M$77,"Fleet-footed",$U$27:$U$77)>0,1,0)) | Q14: Species Move (+1 Fleet-footed)
A15: Other modifier | B15: 0 | C15: 0 | D15: 0 | E15: 0 | F15: 0 | G15: 0 | H15: 0 | I15: 0 | J15: 0 | K15: 0 | M15: Walk / Run | O15: =IF(O14="","",O14*2&" / "&O14*4) | Q15: Walk = 2×M, Run = 4×M (yards per round)
A16: CURRENT | B16: =N(B11)+N(B12)+N(B14)+N(B15) | C16: =N(C11)+N(C12)+N(C14)+N(C15) | D16: =N(D11)+N(D12)+N(D14)+N(D15) | E16: =N(E11)+N(E12)+N(E14)+N(E15) | F16: =N(F11)+N(F12)+N(F14)+N(F15) | G16: =N(G11)+N(G12)+N(G14)+N(G15) | H16: =N(H11)+N(H12)+N(H14)+N(H15) | I16: =N(I11)+N(I12)+N(I14)+N(I15) | ... K16: =N(K11)+N(K12)+N(K14)+N(K15) | M16: Encumbrance | O16: =Equipment!$B$90 | P16: =$D$17*IF(SUMIF($M$27:$M$77,"Sturdy",$U$27:$U$77)>0,2,1)+$E$17+IF(SUMIF($M$27:$M$77,"Strong Back",$U$27:$U$77)>=2,3,SUMIF($M$27:$M$77,"Strong Back",$U$27:$U$77))+N(O17) | Q16: Carried (Equipment tab) / max SB + TB (SB×2 Sturdy, +Strong Back)
A17: Bonus | B17: =INT(B16/10) | C17: =INT(C16/10) | D17: =INT(D16/10) | E17: =INT(E16/10) | F17: =INT(F16/10) | G17: =INT(G16/10) | H17: =INT(H16/10) | I17: =INT(I16/10) | ... K17: =INT(K16/10) | M17: Max Enc adjust | O17: 0 | Q17: GM rulings, Dwarf house rule etc.
A18: Career characteristic (★ now, Ln = opens at level n) | B18: =IF($O$3="","",IFERROR(IF(INDEX(Data_Careers!$P:$P,MATCH($O$3&"|1",Data_Careers!$A:$A,0))="","",IF(INDEX(Data_Careers!$P:$P,MATCH($O$3&"|1",Data_Careers!$A:$A,0))<=N($B$4),"★","L"&INDEX(Data_Careers!$P:$P,MATCH($O$3&"|1",Data_Careers!$A:$A,0)))),"")) | C18: =IF($O$3="","",IFERROR(IF(INDEX(Data_Careers!$Q:$Q,MATCH($O$3&"|1",Data_Careers!$A:$A,0))="","",IF(INDEX(Data_Careers!$Q:$Q,MATCH($O$3&"|1",Data_Careers!$A:$A,0))<=N($B$4),"★","L"&INDEX(Data_Careers!$Q:$Q,MATCH($O$3&"|1",Data_Careers!$A:$A,0)))),"")) | D18: =IF($O$3="","",IFERROR(IF(INDEX(Data_Careers!$R:$R,MATCH($O$3&"|1",Data_Careers!$A:$A,0))="","",IF(INDEX(Data_Careers!$R:$R,MATCH($O$3&"|1",Data_Careers!$A:$A,0))<=N($B$4),"★","L"&INDEX(Data_Careers!$R:$R,MATCH($O$3&"|1",Data_Careers!$A:$A,0)))),"")) | E18: =IF($O$3="","",IFERROR(IF(INDEX(Data_Careers!$S:$S,MATCH($O$3&"|1",Data_Careers!$A:$A,0))="","",IF(INDEX(Data_Careers!$S:$S,MATCH($O$3&"|1",Data_Careers!$A:$A,0))<=N($B$4),"★","L"&INDEX(Data_Careers!$S:$S,MATCH($O$3&"|1",Data_Careers!$A:$A,0)))),"")) | F18: =IF($O$3="","",IFERROR(IF(INDEX(Data_Careers!$T:$T,MATCH($O$3&"|1",Data_Careers!$A:$A,0))="","",IF(INDEX(Data_Careers!$T:$T,MATCH($O$3&"|1",Data_Careers!$A:$A,0))<=N($B$4),"★","L"&INDEX(Data_Careers!$T:$T,MATCH($O$3&"|1",Data_Careers!$A:$A,0)))),"")) | G18: =IF($O$3="","",IFERROR(IF(INDEX(Data_Careers!$U:$U,MATCH($O$3&"|1",Data_Careers!$A:$A,0))="","",IF(INDEX(Data_Careers!$U:$U,MATCH($O$3&"|1",Data_Careers!$A:$A,0))<=N($B$4),"★","L"&INDEX(Data_Careers!$U:$U,MATCH($O$3&"|1",Data_Careers!$A:$A,0)))),"")) | H18: =IF($O$3="","",IFERROR(IF(INDEX(Data_Careers!$V:$V,MATCH($O$3&"|1",Data_Careers!$A:$A,0))="","",IF(INDEX(Data_Careers!$V:$V,MATCH($O$3&"|1",Data_Careers!$A:$A,0))<=N($B$4),"★","L"&INDEX(Data_Careers!$V:$V,MATCH($O$3&"|1",Data_Careers!$A:$A,0)))),"")) | I18: =IF($O$3="","",IFERROR(IF(INDEX(Data_Careers!$W:$W,MATCH($O$3&"|1",Data_Careers!$A:$A,0))="","",IF(INDEX(Data_Careers!$W:$W,MATCH($O$3&"|1",Data_Careers!$A:$A,0))<=N($B$4),"★","L"&INDEX(Data_Careers!$W:$W,MATCH($O$3&"|1",Data_Careers!$A:$A,0)))),"")) | J18: =IF($O$3="","",IFERROR(IF(INDEX(Data_Careers!$X:$X,MATCH($O$3&"|1",Data_Careers!$A:$A,0))="","",IF(INDEX(Data_Careers!$X:$X,MATCH($O$3&"|1",Data_Careers!$A:$A,0))<=N($B$4),"★","L"&INDEX(Data_Careers!$X:$X,MATCH($O$3&"|1",Data_Careers!$A:$A,0)))),"")) | K18: =IF($O$3="","",IFERROR(IF(INDEX(Data_Careers!$Y:$Y,MATCH($O$3&"|1",Data_Careers!$A:$A,0))="","",IF(INDEX(Data_Careers!$Y:$Y,MATCH($O$3&"|1",Data_Careers!$A:$A,0))<=N($B$4),"★","L"&INDEX(Data_Careers!$Y:$Y,MATCH($O$3&"|1",Data_Careers!$A:$A,0)))),"")) | M18: Career ticks | P18: =IF(N($B$4)>=4,"top",IF(N($B$4)=0,"",CHOOSE($B$4,10,12,14))) | Q18: Ticks needed to reach the next level
A19: XP spent | B19: =IFERROR(2*INDEX(Data_Lists!$AF$2:$AF$17,N(B12)/5+1)-INDEX(Data_Lists!$AF$2:$AF$17,(N(B12)-N(B13))/5+1),"?") | C19: =IFERROR(2*INDEX(Data_Lists!$AF$2:$AF$17,N(C12)/5+1)-INDEX(Data_Lists!$AF$2:$AF$17,(N(C12)-N(C13))/5+1),"?") | D19: =IFERROR(2*INDEX(Data_Lists!$AF$2:$AF$17,N(D12)/5+1)-INDEX(Data_Lists!$AF$2:$AF$17,(N(D12)-N(D13))/5+1),"?") | E19: =IFERROR(2*INDEX(Data_Lists!$AF$2:$AF$17,N(E12)/5+1)-INDEX(Data_Lists!$AF$2:$AF$17,(N(E12)-N(E13))/5+1),"?") | F19: =IFERROR(2*INDEX(Data_Lists!$AF$2:$AF$17,N(F12)/5+1)-INDEX(Data_Lists!$AF$2:$AF$17,(N(F12)-N(F13))/5+1),"?") | G19: =IFERROR(2*INDEX(Data_Lists!$AF$2:$AF$17,N(G12)/5+1)-INDEX(Data_Lists!$AF$2:$AF$17,(N(G12)-N(G13))/5+1),"?") | H19: =IFERROR(2*INDEX(Data_Lists!$AF$2:$AF$17,N(H12)/5+1)-INDEX(Data_Lists!$AF$2:$AF$17,(N(H12)-N(H13))/5+1),"?") | I19: =IFERROR(2*INDEX(Data_Lists!$AF$2:$AF$17,N(I12)/5+1)-INDEX(Data_Lists!$AF$2:$AF$17,(N(I12)-N(I13))/5+1),"?") | ... K19: =IFERROR(2*INDEX(Data_Lists!$AF$2:$AF$17,N(K12)/5+1)-INDEX(Data_Lists!$AF$2:$AF$17,(N(K12)-N(K13))/5+1),"?")
A21: EXPERIENCE
A22: XP earned | C22: XP spent | E22: =B23+E23+H23+K23+O23+N(R22) | F22: XP available | H22: =N(B22)-E22 | M22: Other XP spent (endeavours, training…) | R22: 0
A23: Characteristics | B23: =SUM(B19:K19) | C23: Skills | E23: =SUM(H27:H77) | F23: Talents | H23: =SUM(R27:R77) | I23: Careers | K23: =SUM(I81:I86) | M23: Spells & Prayers | O23: ='Spells & Prayers'!$B$4
A25: SKILLS | M25: TALENTS
A26: Skill | B26: Char | C26: Char value | D26: Starting adv (free) | E26: Total adv | F26: …non-career | G26: Skill value | H26: XP cost | I26: Career skill | M26: Talent | P26: Times taken | Q26: Bought with XP? | R26: XP cost | S26: Career talent
A27: Art | B27: =IF(A27="","",IFERROR(IFERROR(INDEX(Data_Skills!$C:$C,MATCH(A27,Data_Skills!$A:$A,0))&"",INDEX(Data_Skills!$C:$C,MATCH(TRIM(IFERROR(LEFT(A27,FIND("(",A27)-1),A27)),Data_Skills!$B:$B,0))&""),"")) | C27: =IF(B27="","",INDEX($B$16:$K$16,MATCH(B27,$B$10:$K$10,0))) | D27: 0 | E27: 0 | F27: 0 | G27: =IF(OR(A27="",C27=""),"",C27+N(E27)) | H27: =IF(A27="","",IFERROR(MAX(0,2*INDEX(Data_Lists!$AG$2:$AG$17,N(E27)/5+1)-INDEX(Data_Lists!$AG$2:$AG$17,N(D27)/5+1)-INDEX(Data_Lists!$AG$2:$AG$17,(N(E27)-N(F27))/5+1)),"?")) | I27: =IF(OR(A27="",$O$3=""),"",IF(OR(ISNUMBER(SEARCH("|"&A27&"|",IFERROR(INDEX(Data_Careers!$J:$J,MATCH($O$3&"|"&$B$4,Data_Careers!$A:$A,0)),""))),ISNUMBER(SEARCH("|"&TRIM(IFERROR(LEFT(A27,FIND("(",A27)-1),A27))&" (any)|",IFERROR(INDEX(Data_Careers!$J:$J,MATCH($O$3&"|"&$B$4,Data_Careers!$A:$A,0)),"")))),"★","")) | R27: =IF(M27="","",IF(Q27="Yes",100*U27,0)) | S27: =IF(OR(M27="",$O$3=""),"",IF(OR(ISNUMBER(SEARCH("|"&M27&"|",IFERROR(INDEX(Data_Careers!$K:$K,MATCH($O$3&"|"&$B$4,Data_Careers!$A:$A,0)),""))),ISNUMBER(SEARCH("|"&TRIM(IFERROR(LEFT(M27,FIND("(",M27)-1),M27))&" (any)|",IFERROR(INDEX(Data_Careers!$K:$K,MATCH($O$3&"|"&$B$4,Data_Careers!$A:$A,0)),"")))),"★","")) | T27: =IF(M27="","",IFERROR(IFERROR(INDEX(Data_Talents!$D:$D,MATCH(M27,Data_Talents!$A:$A,0))&"",INDEX(Data_Talents!$D:$D,MATCH(TRIM(IFERROR(LEFT(M27,FIND("(",M27)-1),M27)),Data_Talents!$B:$B,0))&""),"")) | U27: =IF(M27="",0,IF(N(P27)=0,1,N(P27)))
A28: Athletics | B28: =IF(A28="","",IFERROR(IFERROR(INDEX(Data_Skills!$C:$C,MATCH(A28,Data_Skills!$A:$A,0))&"",INDEX(Data_Skills!$C:$C,MATCH(TRIM(IFERROR(LEFT(A28,FIND("(",A28)-1),A28)),Data_Skills!$B:$B,0))&""),"")) | C28: =IF(B28="","",INDEX($B$16:$K$16,MATCH(B28,$B$10:$K$10,0))) | D28: 0 | E28: 0 | F28: 0 | G28: =IF(OR(A28="",C28=""),"",C28+N(E28)) | H28: =IF(A28="","",IFERROR(MAX(0,2*INDEX(Data_Lists!$AG$2:$AG$17,N(E28)/5+1)-INDEX(Data_Lists!$AG$2:$AG$17,N(D28)/5+1)-INDEX(Data_Lists!$AG$2:$AG$17,(N(E28)-N(F28))/5+1)),"?")) | I28: =IF(OR(A28="",$O$3=""),"",IF(OR(ISNUMBER(SEARCH("|"&A28&"|",IFERROR(INDEX(Data_Careers!$J:$J,MATCH($O$3&"|"&$B$4,Data_Careers!$A:$A,0)),""))),ISNUMBER(SEARCH("|"&TRIM(IFERROR(LEFT(A28,FIND("(",A28)-1),A28))&" (any)|",IFERROR(INDEX(Data_Careers!$J:$J,MATCH($O$3&"|"&$B$4,Data_Careers!$A:$A,0)),"")))),"★","")) | R28: =IF(M28="","",IF(Q28="Yes",100*U28,0)) | S28: =IF(OR(M28="",$O$3=""),"",IF(OR(ISNUMBER(SEARCH("|"&M28&"|",IFERROR(INDEX(Data_Careers!$K:$K,MATCH($O$3&"|"&$B$4,Data_Careers!$A:$A,0)),""))),ISNUMBER(SEARCH("|"&TRIM(IFERROR(LEFT(M28,FIND("(",M28)-1),M28))&" (any)|",IFERROR(INDEX(Data_Careers!$K:$K,MATCH($O$3&"|"&$B$4,Data_Careers!$A:$A,0)),"")))),"★","")) | T28: =IF(M28="","",IFERROR(IFERROR(INDEX(Data_Talents!$D:$D,MATCH(M28,Data_Talents!$A:$A,0))&"",INDEX(Data_Talents!$D:$D,MATCH(TRIM(IFERROR(LEFT(M28,FIND("(",M28)-1),M28)),Data_Talents!$B:$B,0))&""),"")) | U28: =IF(M28="",0,IF(N(P28)=0,1,N(P28)))
A29: Bribery | B29: =IF(A29="","",IFERROR(IFERROR(INDEX(Data_Skills!$C:$C,MATCH(A29,Data_Skills!$A:$A,0))&"",INDEX(Data_Skills!$C:$C,MATCH(TRIM(IFERROR(LEFT(A29,FIND("(",A29)-1),A29)),Data_Skills!$B:$B,0))&""),"")) | C29: =IF(B29="","",INDEX($B$16:$K$16,MATCH(B29,$B$10:$K$10,0))) | D29: 0 | E29: 0 | F29: 0 | G29: =IF(OR(A29="",C29=""),"",C29+N(E29)) | H29: =IF(A29="","",IFERROR(MAX(0,2*INDEX(Data_Lists!$AG$2:$AG$17,N(E29)/5+1)-INDEX(Data_Lists!$AG$2:$AG$17,N(D29)/5+1)-INDEX(Data_Lists!$AG$2:$AG$17,(N(E29)-N(F29))/5+1)),"?")) | I29: =IF(OR(A29="",$O$3=""),"",IF(OR(ISNUMBER(SEARCH("|"&A29&"|",IFERROR(INDEX(Data_Careers!$J:$J,MATCH($O$3&"|"&$B$4,Data_Careers!$A:$A,0)),""))),ISNUMBER(SEARCH("|"&TRIM(IFERROR(LEFT(A29,FIND("(",A29)-1),A29))&" (any)|",IFERROR(INDEX(Data_Careers!$J:$J,MATCH($O$3&"|"&$B$4,Data_Careers!$A:$A,0)),"")))),"★","")) | R29: =IF(M29="","",IF(Q29="Yes",100*U29,0)) | S29: =IF(OR(M29="",$O$3=""),"",IF(OR(ISNUMBER(SEARCH("|"&M29&"|",IFERROR(INDEX(Data_Careers!$K:$K,MATCH($O$3&"|"&$B$4,Data_Careers!$A:$A,0)),""))),ISNUMBER(SEARCH("|"&TRIM(IFERROR(LEFT(M29,FIND("(",M29)-1),M29))&" (any)|",IFERROR(INDEX(Data_Careers!$K:$K,MATCH($O$3&"|"&$B$4,Data_Careers!$A:$A,0)),"")))),"★","")) | T29: =IF(M29="","",IFERROR(IFERROR(INDEX(Data_Talents!$D:$D,MATCH(M29,Data_Talents!$A:$A,0))&"",INDEX(Data_Talents!$D:$D,MATCH(TRIM(IFERROR(LEFT(M29,FIND("(",M29)-1),M29)),Data_Talents!$B:$B,0))&""),"")) | U29: =IF(M29="",0,IF(N(P29)=0,1,N(P29)))
A30: Charm | B30: =IF(A30="","",IFERROR(IFERROR(INDEX(Data_Skills!$C:$C,MATCH(A30,Data_Skills!$A:$A,0))&"",INDEX(Data_Skills!$C:$C,MATCH(TRIM(IFERROR(LEFT(A30,FIND("(",A30)-1),A30)),Data_Skills!$B:$B,0))&""),"")) | C30: =IF(B30="","",INDEX($B$16:$K$16,MATCH(B30,$B$10:$K$10,0))) | D30: 0 | E30: 0 | F30: 0 | G30: =IF(OR(A30="",C30=""),"",C30+N(E30)) | H30: =IF(A30="","",IFERROR(MAX(0,2*INDEX(Data_Lists!$AG$2:$AG$17,N(E30)/5+1)-INDEX(Data_Lists!$AG$2:$AG$17,N(D30)/5+1)-INDEX(Data_Lists!$AG$2:$AG$17,(N(E30)-N(F30))/5+1)),"?")) | I30: =IF(OR(A30="",$O$3=""),"",IF(OR(ISNUMBER(SEARCH("|"&A30&"|",IFERROR(INDEX(Data_Careers!$J:$J,MATCH($O$3&"|"&$B$4,Data_Careers!$A:$A,0)),""))),ISNUMBER(SEARCH("|"&TRIM(IFERROR(LEFT(A30,FIND("(",A30)-1),A30))&" (any)|",IFERROR(INDEX(Data_Careers!$J:$J,MATCH($O$3&"|"&$B$4,Data_Careers!$A:$A,0)),"")))),"★","")) | R30: =IF(M30="","",IF(Q30="Yes",100*U30,0)) | S30: =IF(OR(M30="",$O$3=""),"",IF(OR(ISNUMBER(SEARCH("|"&M30&"|",IFERROR(INDEX(Data_Careers!$K:$K,MATCH($O$3&"|"&$B$4,Data_Careers!$A:$A,0)),""))),ISNUMBER(SEARCH("|"&TRIM(IFERROR(LEFT(M30,FIND("(",M30)-1),M30))&" (any)|",IFERROR(INDEX(Data_Careers!$K:$K,MATCH($O$3&"|"&$B$4,Data_Careers!$A:$A,0)),"")))),"★","")) | T30: =IF(M30="","",IFERROR(IFERROR(INDEX(Data_Talents!$D:$D,MATCH(M30,Data_Talents!$A:$A,0))&"",INDEX(Data_Talents!$D:$D,MATCH(TRIM(IFERROR(LEFT(M30,FIND("(",M30)-1),M30)),Data_Talents!$B:$B,0))&""),"")) | U30: =IF(M30="",0,IF(N(P30)=0,1,N(P30)))
A31: Charm Animal | B31: =IF(A31="","",IFERROR(IFERROR(INDEX(Data_Skills!$C:$C,MATCH(A31,Data_Skills!$A:$A,0))&"",INDEX(Data_Skills!$C:$C,MATCH(TRIM(IFERROR(LEFT(A31,FIND("(",A31)-1),A31)),Data_Skills!$B:$B,0))&""),"")) | C31: =IF(B31="","",INDEX($B$16:$K$16,MATCH(B31,$B$10:$K$10,0))) | D31: 0 | E31: 0 | F31: 0 | G31: =IF(OR(A31="",C31=""),"",C31+N(E31)) | H31: =IF(A31="","",IFERROR(MAX(0,2*INDEX(Data_Lists!$AG$2:$AG$17,N(E31)/5+1)-INDEX(Data_Lists!$AG$2:$AG$17,N(D31)/5+1)-INDEX(Data_Lists!$AG$2:$AG$17,(N(E31)-N(F31))/5+1)),"?")) | I31: =IF(OR(A31="",$O$3=""),"",IF(OR(ISNUMBER(SEARCH("|"&A31&"|",IFERROR(INDEX(Data_Careers!$J:$J,MATCH($O$3&"|"&$B$4,Data_Careers!$A:$A,0)),""))),ISNUMBER(SEARCH("|"&TRIM(IFERROR(LEFT(A31,FIND("(",A31)-1),A31))&" (any)|",IFERROR(INDEX(Data_Careers!$J:$J,MATCH($O$3&"|"&$B$4,Data_Careers!$A:$A,0)),"")))),"★","")) | R31: =IF(M31="","",IF(Q31="Yes",100*U31,0)) | S31: =IF(OR(M31="",$O$3=""),"",IF(OR(ISNUMBER(SEARCH("|"&M31&"|",IFERROR(INDEX(Data_Careers!$K:$K,MATCH($O$3&"|"&$B$4,Data_Careers!$A:$A,0)),""))),ISNUMBER(SEARCH("|"&TRIM(IFERROR(LEFT(M31,FIND("(",M31)-1),M31))&" (any)|",IFERROR(INDEX(Data_Careers!$K:$K,MATCH($O$3&"|"&$B$4,Data_Careers!$A:$A,0)),"")))),"★","")) | T31: =IF(M31="","",IFERROR(IFERROR(INDEX(Data_Talents!$D:$D,MATCH(M31,Data_Talents!$A:$A,0))&"",INDEX(Data_Talents!$D:$D,MATCH(TRIM(IFERROR(LEFT(M31,FIND("(",M31)-1),M31)),Data_Talents!$B:$B,0))&""),"")) | U31: =IF(M31="",0,IF(N(P31)=0,1,N(P31)))
A32: Climb | B32: =IF(A32="","",IFERROR(IFERROR(INDEX(Data_Skills!$C:$C,MATCH(A32,Data_Skills!$A:$A,0))&"",INDEX(Data_Skills!$C:$C,MATCH(TRIM(IFERROR(LEFT(A32,FIND("(",A32)-1),A32)),Data_Skills!$B:$B,0))&""),"")) | C32: =IF(B32="","",INDEX($B$16:$K$16,MATCH(B32,$B$10:$K$10,0))) | D32: 0 | E32: 0 | F32: 0 | G32: =IF(OR(A32="",C32=""),"",C32+N(E32)) | H32: =IF(A32="","",IFERROR(MAX(0,2*INDEX(Data_Lists!$AG$2:$AG$17,N(E32)/5+1)-INDEX(Data_Lists!$AG$2:$AG$17,N(D32)/5+1)-INDEX(Data_Lists!$AG$2:$AG$17,(N(E32)-N(F32))/5+1)),"?")) | I32: =IF(OR(A32="",$O$3=""),"",IF(OR(ISNUMBER(SEARCH("|"&A32&"|",IFERROR(INDEX(Data_Careers!$J:$J,MATCH($O$3&"|"&$B$4,Data_Careers!$A:$A,0)),""))),ISNUMBER(SEARCH("|"&TRIM(IFERROR(LEFT(A32,FIND("(",A32)-1),A32))&" (any)|",IFERROR(INDEX(Data_Careers!$J:$J,MATCH($O$3&"|"&$B$4,Data_Careers!$A:$A,0)),"")))),"★","")) | R32: =IF(M32="","",IF(Q32="Yes",100*U32,0)) | S32: =IF(OR(M32="",$O$3=""),"",IF(OR(ISNUMBER(SEARCH("|"&M32&"|",IFERROR(INDEX(Data_Careers!$K:$K,MATCH($O$3&"|"&$B$4,Data_Careers!$A:$A,0)),""))),ISNUMBER(SEARCH("|"&TRIM(IFERROR(LEFT(M32,FIND("(",M32)-1),M32))&" (any)|",IFERROR(INDEX(Data_Careers!$K:$K,MATCH($O$3&"|"&$B$4,Data_Careers!$A:$A,0)),"")))),"★","")) | T32: =IF(M32="","",IFERROR(IFERROR(INDEX(Data_Talents!$D:$D,MATCH(M32,Data_Talents!$A:$A,0))&"",INDEX(Data_Talents!$D:$D,MATCH(TRIM(IFERROR(LEFT(M32,FIND("(",M32)-1),M32)),Data_Talents!$B:$B,0))&""),"")) | U32: =IF(M32="",0,IF(N(P32)=0,1,N(P32)))
A33: Consume Alcohol | B33: =IF(A33="","",IFERROR(IFERROR(INDEX(Data_Skills!$C:$C,MATCH(A33,Data_Skills!$A:$A,0))&"",INDEX(Data_Skills!$C:$C,MATCH(TRIM(IFERROR(LEFT(A33,FIND("(",A33)-1),A33)),Data_Skills!$B:$B,0))&""),"")) | C33: =IF(B33="","",INDEX($B$16:$K$16,MATCH(B33,$B$10:$K$10,0))) | D33: 0 | E33: 0 | F33: 0 | G33: =IF(OR(A33="",C33=""),"",C33+N(E33)) | H33: =IF(A33="","",IFERROR(MAX(0,2*INDEX(Data_Lists!$AG$2:$AG$17,N(E33)/5+1)-INDEX(Data_Lists!$AG$2:$AG$17,N(D33)/5+1)-INDEX(Data_Lists!$AG$2:$AG$17,(N(E33)-N(F33))/5+1)),"?")) | I33: =IF(OR(A33="",$O$3=""),"",IF(OR(ISNUMBER(SEARCH("|"&A33&"|",IFERROR(INDEX(Data_Careers!$J:$J,MATCH($O$3&"|"&$B$4,Data_Careers!$A:$A,0)),""))),ISNUMBER(SEARCH("|"&TRIM(IFERROR(LEFT(A33,FIND("(",A33)-1),A33))&" (any)|",IFERROR(INDEX(Data_Careers!$J:$J,MATCH($O$3&"|"&$B$4,Data_Careers!$A:$A,0)),"")))),"★","")) | R33: =IF(M33="","",IF(Q33="Yes",100*U33,0)) | S33: =IF(OR(M33="",$O$3=""),"",IF(OR(ISNUMBER(SEARCH("|"&M33&"|",IFERROR(INDEX(Data_Careers!$K:$K,MATCH($O$3&"|"&$B$4,Data_Careers!$A:$A,0)),""))),ISNUMBER(SEARCH("|"&TRIM(IFERROR(LEFT(M33,FIND("(",M33)-1),M33))&" (any)|",IFERROR(INDEX(Data_Careers!$K:$K,MATCH($O$3&"|"&$B$4,Data_Careers!$A:$A,0)),"")))),"★","")) | T33: =IF(M33="","",IFERROR(IFERROR(INDEX(Data_Talents!$D:$D,MATCH(M33,Data_Talents!$A:$A,0))&"",INDEX(Data_Talents!$D:$D,MATCH(TRIM(IFERROR(LEFT(M33,FIND("(",M33)-1),M33)),Data_Talents!$B:$B,0))&""),"")) | U33: =IF(M33="",0,IF(N(P33)=0,1,N(P33)))
A34: Cool | B34: =IF(A34="","",IFERROR(IFERROR(INDEX(Data_Skills!$C:$C,MATCH(A34,Data_Skills!$A:$A,0))&"",INDEX(Data_Skills!$C:$C,MATCH(TRIM(IFERROR(LEFT(A34,FIND("(",A34)-1),A34)),Data_Skills!$B:$B,0))&""),"")) | C34: =IF(B34="","",INDEX($B$16:$K$16,MATCH(B34,$B$10:$K$10,0))) | D34: 0 | E34: 0 | F34: 0 | G34: =IF(OR(A34="",C34=""),"",C34+N(E34)) | H34: =IF(A34="","",IFERROR(MAX(0,2*INDEX(Data_Lists!$AG$2:$AG$17,N(E34)/5+1)-INDEX(Data_Lists!$AG$2:$AG$17,N(D34)/5+1)-INDEX(Data_Lists!$AG$2:$AG$17,(N(E34)-N(F34))/5+1)),"?")) | I34: =IF(OR(A34="",$O$3=""),"",IF(OR(ISNUMBER(SEARCH("|"&A34&"|",IFERROR(INDEX(Data_Careers!$J:$J,MATCH($O$3&"|"&$B$4,Data_Careers!$A:$A,0)),""))),ISNUMBER(SEARCH("|"&TRIM(IFERROR(LEFT(A34,FIND("(",A34)-1),A34))&" (any)|",IFERROR(INDEX(Data_Careers!$J:$J,MATCH($O$3&"|"&$B$4,Data_Careers!$A:$A,0)),"")))),"★","")) | R34: =IF(M34="","",IF(Q34="Yes",100*U34,0)) | S34: =IF(OR(M34="",$O$3=""),"",IF(OR(ISNUMBER(SEARCH("|"&M34&"|",IFERROR(INDEX(Data_Careers!$K:$K,MATCH($O$3&"|"&$B$4,Data_Careers!$A:$A,0)),""))),ISNUMBER(SEARCH("|"&TRIM(IFERROR(LEFT(M34,FIND("(",M34)-1),M34))&" (any)|",IFERROR(INDEX(Data_Careers!$K:$K,MATCH($O$3&"|"&$B$4,Data_Careers!$A:$A,0)),"")))),"★","")) | T34: =IF(M34="","",IFERROR(IFERROR(INDEX(Data_Talents!$D:$D,MATCH(M34,Data_Talents!$A:$A,0))&"",INDEX(Data_Talents!$D:$D,MATCH(TRIM(IFERROR(LEFT(M34,FIND("(",M34)-1),M34)),Data_Talents!$B:$B,0))&""),"")) | U34: =IF(M34="",0,IF(N(P34)=0,1,N(P34)))
A35: Dodge | B35: =IF(A35="","",IFERROR(IFERROR(INDEX(Data_Skills!$C:$C,MATCH(A35,Data_Skills!$A:$A,0))&"",INDEX(Data_Skills!$C:$C,MATCH(TRIM(IFERROR(LEFT(A35,FIND("(",A35)-1),A35)),Data_Skills!$B:$B,0))&""),"")) | C35: =IF(B35="","",INDEX($B$16:$K$16,MATCH(B35,$B$10:$K$10,0))) | D35: 0 | E35: 0 | F35: 0 | G35: =IF(OR(A35="",C35=""),"",C35+N(E35)) | H35: =IF(A35="","",IFERROR(MAX(0,2*INDEX(Data_Lists!$AG$2:$AG$17,N(E35)/5+1)-INDEX(Data_Lists!$AG$2:$AG$17,N(D35)/5+1)-INDEX(Data_Lists!$AG$2:$AG$17,(N(E35)-N(F35))/5+1)),"?")) | I35: =IF(OR(A35="",$O$3=""),"",IF(OR(ISNUMBER(SEARCH("|"&A35&"|",IFERROR(INDEX(Data_Careers!$J:$J,MATCH($O$3&"|"&$B$4,Data_Careers!$A:$A,0)),""))),ISNUMBER(SEARCH("|"&TRIM(IFERROR(LEFT(A35,FIND("(",A35)-1),A35))&" (any)|",IFERROR(INDEX(Data_Careers!$J:$J,MATCH($O$3&"|"&$B$4,Data_Careers!$A:$A,0)),"")))),"★","")) | R35: =IF(M35="","",IF(Q35="Yes",100*U35,0)) | S35: =IF(OR(M35="",$O$3=""),"",IF(OR(ISNUMBER(SEARCH("|"&M35&"|",IFERROR(INDEX(Data_Careers!$K:$K,MATCH($O$3&"|"&$B$4,Data_Careers!$A:$A,0)),""))),ISNUMBER(SEARCH("|"&TRIM(IFERROR(LEFT(M35,FIND("(",M35)-1),M35))&" (any)|",IFERROR(INDEX(Data_Careers!$K:$K,MATCH($O$3&"|"&$B$4,Data_Careers!$A:$A,0)),"")))),"★","")) | T35: =IF(M35="","",IFERROR(IFERROR(INDEX(Data_Talents!$D:$D,MATCH(M35,Data_Talents!$A:$A,0))&"",INDEX(Data_Talents!$D:$D,MATCH(TRIM(IFERROR(LEFT(M35,FIND("(",M35)-1),M35)),Data_Talents!$B:$B,0))&""),"")) | U35: =IF(M35="",0,IF(N(P35)=0,1,N(P35)))
A36: Drive | B36: =IF(A36="","",IFERROR(IFERROR(INDEX(Data_Skills!$C:$C,MATCH(A36,Data_Skills!$A:$A,0))&"",INDEX(Data_Skills!$C:$C,MATCH(TRIM(IFERROR(LEFT(A36,FIND("(",A36)-1),A36)),Data_Skills!$B:$B,0))&""),"")) | C36: =IF(B36="","",INDEX($B$16:$K$16,MATCH(B36,$B$10:$K$10,0))) | D36: 0 | E36: 0 | F36: 0 | G36: =IF(OR(A36="",C36=""),"",C36+N(E36)) | H36: =IF(A36="","",IFERROR(MAX(0,2*INDEX(Data_Lists!$AG$2:$AG$17,N(E36)/5+1)-INDEX(Data_Lists!$AG$2:$AG$17,N(D36)/5+1)-INDEX(Data_Lists!$AG$2:$AG$17,(N(E36)-N(F36))/5+1)),"?")) | I36: =IF(OR(A36="",$O$3=""),"",IF(OR(ISNUMBER(SEARCH("|"&A36&"|",IFERROR(INDEX(Data_Careers!$J:$J,MATCH($O$3&"|"&$B$4,Data_Careers!$A:$A,0)),""))),ISNUMBER(SEARCH("|"&TRIM(IFERROR(LEFT(A36,FIND("(",A36)-1),A36))&" (any)|",IFERROR(INDEX(Data_Careers!$J:$J,MATCH($O$3&"|"&$B$4,Data_Careers!$A:$A,0)),"")))),"★","")) | R36: =IF(M36="","",IF(Q36="Yes",100*U36,0)) | S36: =IF(OR(M36="",$O$3=""),"",IF(OR(ISNUMBER(SEARCH("|"&M36&"|",IFERROR(INDEX(Data_Careers!$K:$K,MATCH($O$3&"|"&$B$4,Data_Careers!$A:$A,0)),""))),ISNUMBER(SEARCH("|"&TRIM(IFERROR(LEFT(M36,FIND("(",M36)-1),M36))&" (any)|",IFERROR(INDEX(Data_Careers!$K:$K,MATCH($O$3&"|"&$B$4,Data_Careers!$A:$A,0)),"")))),"★","")) | T36: =IF(M36="","",IFERROR(IFERROR(INDEX(Data_Talents!$D:$D,MATCH(M36,Data_Talents!$A:$A,0))&"",INDEX(Data_Talents!$D:$D,MATCH(TRIM(IFERROR(LEFT(M36,FIND("(",M36)-1),M36)),Data_Talents!$B:$B,0))&""),"")) | U36: =IF(M36="",0,IF(N(P36)=0,1,N(P36)))
A37: Endurance | B37: =IF(A37="","",IFERROR(IFERROR(INDEX(Data_Skills!$C:$C,MATCH(A37,Data_Skills!$A:$A,0))&"",INDEX(Data_Skills!$C:$C,MATCH(TRIM(IFERROR(LEFT(A37,FIND("(",A37)-1),A37)),Data_Skills!$B:$B,0))&""),"")) | C37: =IF(B37="","",INDEX($B$16:$K$16,MATCH(B37,$B$10:$K$10,0))) | D37: 0 | E37: 0 | F37: 0 | G37: =IF(OR(A37="",C37=""),"",C37+N(E37)) | H37: =IF(A37="","",IFERROR(MAX(0,2*INDEX(Data_Lists!$AG$2:$AG$17,N(E37)/5+1)-INDEX(Data_Lists!$AG$2:$AG$17,N(D37)/5+1)-INDEX(Data_Lists!$AG$2:$AG$17,(N(E37)-N(F37))/5+1)),"?")) | I37: =IF(OR(A37="",$O$3=""),"",IF(OR(ISNUMBER(SEARCH("|"&A37&"|",IFERROR(INDEX(Data_Careers!$J:$J,MATCH($O$3&"|"&$B$4,Data_Careers!$A:$A,0)),""))),ISNUMBER(SEARCH("|"&TRIM(IFERROR(LEFT(A37,FIND("(",A37)-1),A37))&" (any)|",IFERROR(INDEX(Data_Careers!$J:$J,MATCH($O$3&"|"&$B$4,Data_Careers!$A:$A,0)),"")))),"★","")) | R37: =IF(M37="","",IF(Q37="Yes",100*U37,0)) | S37: =IF(OR(M37="",$O$3=""),"",IF(OR(ISNUMBER(SEARCH("|"&M37&"|",IFERROR(INDEX(Data_Careers!$K:$K,MATCH($O$3&"|"&$B$4,Data_Careers!$A:$A,0)),""))),ISNUMBER(SEARCH("|"&TRIM(IFERROR(LEFT(M37,FIND("(",M37)-1),M37))&" (any)|",IFERROR(INDEX(Data_Careers!$K:$K,MATCH($O$3&"|"&$B$4,Data_Careers!$A:$A,0)),"")))),"★","")) | T37: =IF(M37="","",IFERROR(IFERROR(INDEX(Data_Talents!$D:$D,MATCH(M37,Data_Talents!$A:$A,0))&"",INDEX(Data_Talents!$D:$D,MATCH(TRIM(IFERROR(LEFT(M37,FIND("(",M37)-1),M37)),Data_Talents!$B:$B,0))&""),"")) | U37: =IF(M37="",0,IF(N(P37)=0,1,N(P37)))
A38: Entertain | B38: =IF(A38="","",IFERROR(IFERROR(INDEX(Data_Skills!$C:$C,MATCH(A38,Data_Skills!$A:$A,0))&"",INDEX(Data_Skills!$C:$C,MATCH(TRIM(IFERROR(LEFT(A38,FIND("(",A38)-1),A38)),Data_Skills!$B:$B,0))&""),"")) | C38: =IF(B38="","",INDEX($B$16:$K$16,MATCH(B38,$B$10:$K$10,0))) | D38: 0 | E38: 0 | F38: 0 | G38: =IF(OR(A38="",C38=""),"",C38+N(E38)) | H38: =IF(A38="","",IFERROR(MAX(0,2*INDEX(Data_Lists!$AG$2:$AG$17,N(E38)/5+1)-INDEX(Data_Lists!$AG$2:$AG$17,N(D38)/5+1)-INDEX(Data_Lists!$AG$2:$AG$17,(N(E38)-N(F38))/5+1)),"?")) | I38: =IF(OR(A38="",$O$3=""),"",IF(OR(ISNUMBER(SEARCH("|"&A38&"|",IFERROR(INDEX(Data_Careers!$J:$J,MATCH($O$3&"|"&$B$4,Data_Careers!$A:$A,0)),""))),ISNUMBER(SEARCH("|"&TRIM(IFERROR(LEFT(A38,FIND("(",A38)-1),A38))&" (any)|",IFERROR(INDEX(Data_Careers!$J:$J,MATCH($O$3&"|"&$B$4,Data_Careers!$A:$A,0)),"")))),"★","")) | R38: =IF(M38="","",IF(Q38="Yes",100*U38,0)) | S38: =IF(OR(M38="",$O$3=""),"",IF(OR(ISNUMBER(SEARCH("|"&M38&"|",IFERROR(INDEX(Data_Careers!$K:$K,MATCH($O$3&"|"&$B$4,Data_Careers!$A:$A,0)),""))),ISNUMBER(SEARCH("|"&TRIM(IFERROR(LEFT(M38,FIND("(",M38)-1),M38))&" (any)|",IFERROR(INDEX(Data_Careers!$K:$K,MATCH($O$3&"|"&$B$4,Data_Careers!$A:$A,0)),"")))),"★","")) | T38: =IF(M38="","",IFERROR(IFERROR(INDEX(Data_Talents!$D:$D,MATCH(M38,Data_Talents!$A:$A,0))&"",INDEX(Data_Talents!$D:$D,MATCH(TRIM(IFERROR(LEFT(M38,FIND("(",M38)-1),M38)),Data_Talents!$B:$B,0))&""),"")) | U38: =IF(M38="",0,IF(N(P38)=0,1,N(P38)))
... A52: Stealth | B52: =IF(A52="","",IFERROR(IFERROR(INDEX(Data_Skills!$C:$C,MATCH(A52,Data_Skills!$A:$A,0))&"",INDEX(Data_Skills!$C:$C,MATCH(TRIM(IFERROR(LEFT(A52,FIND("(",A52)-1),A52)),Data_Skills!$B:$B,0))&""),"")) | C52: =IF(B52="","",INDEX($B$16:$K$16,MATCH(B52,$B$10:$K$10,0))) | D52: 0 | E52: 0 | F52: 0 | G52: =IF(OR(A52="",C52=""),"",C52+N(E52)) | H52: =IF(A52="","",IFERROR(MAX(0,2*INDEX(Data_Lists!$AG$2:$AG$17,N(E52)/5+1)-INDEX(Data_Lists!$AG$2:$AG$17,N(D52)/5+1)-INDEX(Data_Lists!$AG$2:$AG$17,(N(E52)-N(F52))/5+1)),"?")) | I52: =IF(OR(A52="",$O$3=""),"",IF(OR(ISNUMBER(SEARCH("|"&A52&"|",IFERROR(INDEX(Data_Careers!$J:$J,MATCH($O$3&"|"&$B$4,Data_Careers!$A:$A,0)),""))),ISNUMBER(SEARCH("|"&TRIM(IFERROR(LEFT(A52,FIND("(",A52)-1),A52))&" (any)|",IFERROR(INDEX(Data_Careers!$J:$J,MATCH($O$3&"|"&$B$4,Data_Careers!$A:$A,0)),"")))),"★","")) | R52: =IF(M52="","",IF(Q52="Yes",100*U52,0)) | S52: =IF(OR(M52="",$O$3=""),"",IF(OR(ISNUMBER(SEARCH("|"&M52&"|",IFERROR(INDEX(Data_Careers!$K:$K,MATCH($O$3&"|"&$B$4,Data_Careers!$A:$A,0)),""))),ISNUMBER(SEARCH("|"&TRIM(IFERROR(LEFT(M52,FIND("(",M52)-1),M52))&" (any)|",IFERROR(INDEX(Data_Careers!$K:$K,MATCH($O$3&"|"&$B$4,Data_Careers!$A:$A,0)),"")))),"★","")) | T52: =IF(M52="","",IFERROR(IFERROR(INDEX(Data_Talents!$D:$D,MATCH(M52,Data_Talents!$A:$A,0))&"",INDEX(Data_Talents!$D:$D,MATCH(TRIM(IFERROR(LEFT(M52,FIND("(",M52)-1),M52)),Data_Talents!$B:$B,0))&""),"")) | U52: =IF(M52="",0,IF(N(P52)=0,1,N(P52)))
A53: Advanced & grouped skills — pick from the list (e.g. Language (Reikspiel), Lore (Law)) | R53: =IF(M53="","",IF(Q53="Yes",100*U53,0)) | S53: =IF(OR(M53="",$O$3=""),"",IF(OR(ISNUMBER(SEARCH("|"&M53&"|",IFERROR(INDEX(Data_Careers!$K:$K,MATCH($O$3&"|"&$B$4,Data_Careers!$A:$A,0)),""))),ISNUMBER(SEARCH("|"&TRIM(IFERROR(LEFT(M53,FIND("(",M53)-1),M53))&" (any)|",IFERROR(INDEX(Data_Careers!$K:$K,MATCH($O$3&"|"&$B$4,Data_Careers!$A:$A,0)),"")))),"★","")) | T53: =IF(M53="","",IFERROR(IFERROR(INDEX(Data_Talents!$D:$D,MATCH(M53,Data_Talents!$A:$A,0))&"",INDEX(Data_Talents!$D:$D,MATCH(TRIM(IFERROR(LEFT(M53,FIND("(",M53)-1),M53)),Data_Talents!$B:$B,0))&""),"")) | U53: =IF(M53="",0,IF(N(P53)=0,1,N(P53)))
B54: =IF(A54="","",IFERROR(IFERROR(INDEX(Data_Skills!$C:$C,MATCH(A54,Data_Skills!$A:$A,0))&"",INDEX(Data_Skills!$C:$C,MATCH(TRIM(IFERROR(LEFT(A54,FIND("(",A54)-1),A54)),Data_Skills!$B:$B,0))&""),"")) | C54: =IF(B54="","",INDEX($B$16:$K$16,MATCH(B54,$B$10:$K$10,0))) | G54: =IF(OR(A54="",C54=""),"",C54+N(E54)) | H54: =IF(A54="","",IFERROR(MAX(0,2*INDEX(Data_Lists!$AG$2:$AG$17,N(E54)/5+1)-INDEX(Data_Lists!$AG$2:$AG$17,N(D54)/5+1)-INDEX(Data_Lists!$AG$2:$AG$17,(N(E54)-N(F54))/5+1)),"?")) | I54: =IF(OR(A54="",$O$3=""),"",IF(OR(ISNUMBER(SEARCH("|"&A54&"|",IFERROR(INDEX(Data_Careers!$J:$J,MATCH($O$3&"|"&$B$4,Data_Careers!$A:$A,0)),""))),ISNUMBER(SEARCH("|"&TRIM(IFERROR(LEFT(A54,FIND("(",A54)-1),A54))&" (any)|",IFERROR(INDEX(Data_Careers!$J:$J,MATCH($O$3&"|"&$B$4,Data_Careers!$A:$A,0)),"")))),"★","")) | R54: =IF(M54="","",IF(Q54="Yes",100*U54,0)) | S54: =IF(OR(M54="",$O$3=""),"",IF(OR(ISNUMBER(SEARCH("|"&M54&"|",IFERROR(INDEX(Data_Careers!$K:$K,MATCH($O$3&"|"&$B$4,Data_Careers!$A:$A,0)),""))),ISNUMBER(SEARCH("|"&TRIM(IFERROR(LEFT(M54,FIND("(",M54)-1),M54))&" (any)|",IFERROR(INDEX(Data_Careers!$K:$K,MATCH($O$3&"|"&$B$4,Data_Careers!$A:$A,0)),"")))),"★","")) | T54: =IF(M54="","",IFERROR(IFERROR(INDEX(Data_Talents!$D:$D,MATCH(M54,Data_Talents!$A:$A,0))&"",INDEX(Data_Talents!$D:$D,MATCH(TRIM(IFERROR(LEFT(M54,FIND("(",M54)-1),M54)),Data_Talents!$B:$B,0))&""),"")) | U54: =IF(M54="",0,IF(N(P54)=0,1,N(P54)))
B55: =IF(A55="","",IFERROR(IFERROR(INDEX(Data_Skills!$C:$C,MATCH(A55,Data_Skills!$A:$A,0))&"",INDEX(Data_Skills!$C:$C,MATCH(TRIM(IFERROR(LEFT(A55,FIND("(",A55)-1),A55)),Data_Skills!$B:$B,0))&""),"")) | C55: =IF(B55="","",INDEX($B$16:$K$16,MATCH(B55,$B$10:$K$10,0))) | G55: =IF(OR(A55="",C55=""),"",C55+N(E55)) | H55: =IF(A55="","",IFERROR(MAX(0,2*INDEX(Data_Lists!$AG$2:$AG$17,N(E55)/5+1)-INDEX(Data_Lists!$AG$2:$AG$17,N(D55)/5+1)-INDEX(Data_Lists!$AG$2:$AG$17,(N(E55)-N(F55))/5+1)),"?")) | I55: =IF(OR(A55="",$O$3=""),"",IF(OR(ISNUMBER(SEARCH("|"&A55&"|",IFERROR(INDEX(Data_Careers!$J:$J,MATCH($O$3&"|"&$B$4,Data_Careers!$A:$A,0)),""))),ISNUMBER(SEARCH("|"&TRIM(IFERROR(LEFT(A55,FIND("(",A55)-1),A55))&" (any)|",IFERROR(INDEX(Data_Careers!$J:$J,MATCH($O$3&"|"&$B$4,Data_Careers!$A:$A,0)),"")))),"★","")) | R55: =IF(M55="","",IF(Q55="Yes",100*U55,0)) | S55: =IF(OR(M55="",$O$3=""),"",IF(OR(ISNUMBER(SEARCH("|"&M55&"|",IFERROR(INDEX(Data_Careers!$K:$K,MATCH($O$3&"|"&$B$4,Data_Careers!$A:$A,0)),""))),ISNUMBER(SEARCH("|"&TRIM(IFERROR(LEFT(M55,FIND("(",M55)-1),M55))&" (any)|",IFERROR(INDEX(Data_Careers!$K:$K,MATCH($O$3&"|"&$B$4,Data_Careers!$A:$A,0)),"")))),"★","")) | T55: =IF(M55="","",IFERROR(IFERROR(INDEX(Data_Talents!$D:$D,MATCH(M55,Data_Talents!$A:$A,0))&"",INDEX(Data_Talents!$D:$D,MATCH(TRIM(IFERROR(LEFT(M55,FIND("(",M55)-1),M55)),Data_Talents!$B:$B,0))&""),"")) | U55: =IF(M55="",0,IF(N(P55)=0,1,N(P55)))
B56: =IF(A56="","",IFERROR(IFERROR(INDEX(Data_Skills!$C:$C,MATCH(A56,Data_Skills!$A:$A,0))&"",INDEX(Data_Skills!$C:$C,MATCH(TRIM(IFERROR(LEFT(A56,FIND("(",A56)-1),A56)),Data_Skills!$B:$B,0))&""),"")) | C56: =IF(B56="","",INDEX($B$16:$K$16,MATCH(B56,$B$10:$K$10,0))) | G56: =IF(OR(A56="",C56=""),"",C56+N(E56)) | H56: =IF(A56="","",IFERROR(MAX(0,2*INDEX(Data_Lists!$AG$2:$AG$17,N(E56)/5+1)-INDEX(Data_Lists!$AG$2:$AG$17,N(D56)/5+1)-INDEX(Data_Lists!$AG$2:$AG$17,(N(E56)-N(F56))/5+1)),"?")) | I56: =IF(OR(A56="",$O$3=""),"",IF(OR(ISNUMBER(SEARCH("|"&A56&"|",IFERROR(INDEX(Data_Careers!$J:$J,MATCH($O$3&"|"&$B$4,Data_Careers!$A:$A,0)),""))),ISNUMBER(SEARCH("|"&TRIM(IFERROR(LEFT(A56,FIND("(",A56)-1),A56))&" (any)|",IFERROR(INDEX(Data_Careers!$J:$J,MATCH($O$3&"|"&$B$4,Data_Careers!$A:$A,0)),"")))),"★","")) | R56: =IF(M56="","",IF(Q56="Yes",100*U56,0)) | S56: =IF(OR(M56="",$O$3=""),"",IF(OR(ISNUMBER(SEARCH("|"&M56&"|",IFERROR(INDEX(Data_Careers!$K:$K,MATCH($O$3&"|"&$B$4,Data_Careers!$A:$A,0)),""))),ISNUMBER(SEARCH("|"&TRIM(IFERROR(LEFT(M56,FIND("(",M56)-1),M56))&" (any)|",IFERROR(INDEX(Data_Careers!$K:$K,MATCH($O$3&"|"&$B$4,Data_Careers!$A:$A,0)),"")))),"★","")) | T56: =IF(M56="","",IFERROR(IFERROR(INDEX(Data_Talents!$D:$D,MATCH(M56,Data_Talents!$A:$A,0))&"",INDEX(Data_Talents!$D:$D,MATCH(TRIM(IFERROR(LEFT(M56,FIND("(",M56)-1),M56)),Data_Talents!$B:$B,0))&""),"")) | U56: =IF(M56="",0,IF(N(P56)=0,1,N(P56)))
...

Sheet Career
A1: CAREER
A3: Career | B3: =IF(Character!$O$3="","(choose a career on the Character tab)",Character!$O$3) | D3: =N(Character!$B$4) | E3: ← current level (from Character tab)
A4: Class | B4: =IF(Character!$O$3="","",IFERROR(INDEX(Data_Careers!$D:$D,MATCH(Character!$O$3&"|1",Data_Careers!$A:$A,0))&"",""))
A5: Summary | B5: =IF(Character!$O$3="","",IFERROR(INDEX(Data_Careers!$L:$L,MATCH(Character!$O$3&"|1",Data_Careers!$A:$A,0))&"",""))
A6: Income | B6: =IF(Character!$O$3="","",IFERROR(INDEX(Data_Careers!$M:$M,MATCH(Character!$O$3&"|1",Data_Careers!$A:$A,0))&"","")) | D6: Species: | E6: =IF(Character!$O$3="","",IFERROR(INDEX(Data_Careers!$N:$N,MATCH(Character!$O$3&"|1",Data_Careers!$A:$A,0))&"",""))
A7: Page | B7: =IF(Character!$O$3="","",IFERROR(INDEX(Data_Careers!$O:$O,MATCH(Character!$O$3&"|1",Data_Careers!$A:$A,0))&"",""))
A9: CAREER LEVELS
A10: Level | B10: Title | C10: Status | D10: Skills | E10: Talents | F10: Trappings
A11: 1 | B11: =IF(Character!$O$3="","",IFERROR(INDEX(Data_Careers!$E:$E,MATCH(Character!$O$3&"|1",Data_Careers!$A:$A,0))&"","")) | C11: =IF(Character!$O$3="","",IFERROR(INDEX(Data_Careers!$F:$F,MATCH(Character!$O$3&"|1",Data_Careers!$A:$A,0))&"","")) | D11: =IF(Character!$O$3="","",IFERROR(INDEX(Data_Careers!$G:$G,MATCH(Character!$O$3&"|1",Data_Careers!$A:$A,0))&"","")) | E11: =IF(Character!$O$3="","",IFERROR(INDEX(Data_Careers!$H:$H,MATCH(Character!$O$3&"|1",Data_Careers!$A:$A,0))&"","")) | F11: =IF(Character!$O$3="","",IFERROR(INDEX(Data_Careers!$I:$I,MATCH(Character!$O$3&"|1",Data_Careers!$A:$A,0))&"",""))
A12: 2 | B12: =IF(Character!$O$3="","",IFERROR(INDEX(Data_Careers!$E:$E,MATCH(Character!$O$3&"|2",Data_Careers!$A:$A,0))&"","")) | C12: =IF(Character!$O$3="","",IFERROR(INDEX(Data_Careers!$F:$F,MATCH(Character!$O$3&"|2",Data_Careers!$A:$A,0))&"","")) | D12: =IF(Character!$O$3="","",IFERROR(INDEX(Data_Careers!$G:$G,MATCH(Character!$O$3&"|2",Data_Careers!$A:$A,0))&"","")) | E12: =IF(Character!$O$3="","",IFERROR(INDEX(Data_Careers!$H:$H,MATCH(Character!$O$3&"|2",Data_Careers!$A:$A,0))&"","")) | F12: =IF(Character!$O$3="","",IFERROR(INDEX(Data_Careers!$I:$I,MATCH(Character!$O$3&"|2",Data_Careers!$A:$A,0))&"",""))
A13: 3 | B13: =IF(Character!$O$3="","",IFERROR(INDEX(Data_Careers!$E:$E,MATCH(Character!$O$3&"|3",Data_Careers!$A:$A,0))&"","")) | C13: =IF(Character!$O$3="","",IFERROR(INDEX(Data_Careers!$F:$F,MATCH(Character!$O$3&"|3",Data_Careers!$A:$A,0))&"","")) | D13: =IF(Character!$O$3="","",IFERROR(INDEX(Data_Careers!$G:$G,MATCH(Character!$O$3&"|3",Data_Careers!$A:$A,0))&"","")) | E13: =IF(Character!$O$3="","",IFERROR(INDEX(Data_Careers!$H:$H,MATCH(Character!$O$3&"|3",Data_Careers!$A:$A,0))&"","")) | F13: =IF(Character!$O$3="","",IFERROR(INDEX(Data_Careers!$I:$I,MATCH(Character!$O$3&"|3",Data_Careers!$A:$A,0))&"",""))
A14: 4 | B14: =IF(Character!$O$3="","",IFERROR(INDEX(Data_Careers!$E:$E,MATCH(Character!$O$3&"|4",Data_Careers!$A:$A,0))&"","")) | C14: =IF(Character!$O$3="","",IFERROR(INDEX(Data_Careers!$F:$F,MATCH(Character!$O$3&"|4",Data_Careers!$A:$A,0))&"","")) | D14: =IF(Character!$O$3="","",IFERROR(INDEX(Data_Careers!$G:$G,MATCH(Character!$O$3&"|4",Data_Careers!$A:$A,0))&"","")) | E14: =IF(Character!$O$3="","",IFERROR(INDEX(Data_Careers!$H:$H,MATCH(Character!$O$3&"|4",Data_Careers!$A:$A,0))&"","")) | F14: =IF(Character!$O$3="","",IFERROR(INDEX(Data_Careers!$I:$I,MATCH(Character!$O$3&"|4",Data_Careers!$A:$A,0))&"",""))
A16: STARTING TRAPPINGS
A17: All | B17: Clothing, Dagger, Pouch
A18: Class | B18: =IF(B4="","",IFERROR(INDEX(Data_Lists!$M$2:$M$9,MATCH(B4,Data_Lists!$L$2:$L$9,0)),""))
A19: Career | B19: =F11
A20: Keeping the first career roll grants 2 Trappings from level 2 (1 if you picked from three rolls); each bonus Trapping ticks your Career Advancement tracker.
A22: CHARACTERISTIC ADVANCE SCHEME
A23: Char | B23: Characteristic | C23: Opens at level | D23: Advanceable now
A24: WS | B24: Weapon Skill | C24: =IF(Character!$O$3="","",IFERROR(IF(INDEX(Data_Careers!$P:$P,MATCH(Character!$O$3&"|1",Data_Careers!$A:$A,0))="","",INDEX(Data_Careers!$P:$P,MATCH(Character!$O$3&"|1",Data_Careers!$A:$A,0))),"")) | D24: =IF(C24="","",IF(N(C24)<=$D$3,"★ yes",""))
A25: BS | B25: Ballistic Skill | C25: =IF(Character!$O$3="","",IFERROR(IF(INDEX(Data_Careers!$Q:$Q,MATCH(Character!$O$3&"|1",Data_Careers!$A:$A,0))="","",INDEX(Data_Careers!$Q:$Q,MATCH(Character!$O$3&"|1",Data_Careers!$A:$A,0))),"")) | D25: =IF(C25="","",IF(N(C25)<=$D$3,"★ yes",""))
A26: S | B26: Strength | C26: =IF(Character!$O$3="","",IFERROR(IF(INDEX(Data_Careers!$R:$R,MATCH(Character!$O$3&"|1",Data_Careers!$A:$A,0))="","",INDEX(Data_Careers!$R:$R,MATCH(Character!$O$3&"|1",Data_Careers!$A:$A,0))),"")) | D26: =IF(C26="","",IF(N(C26)<=$D$3,"★ yes",""))
A27: T | B27: Toughness | C27: =IF(Character!$O$3="","",IFERROR(IF(INDEX(Data_Careers!$S:$S,MATCH(Character!$O$3&"|1",Data_Careers!$A:$A,0))="","",INDEX(Data_Careers!$S:$S,MATCH(Character!$O$3&"|1",Data_Careers!$A:$A,0))),"")) | D27: =IF(C27="","",IF(N(C27)<=$D$3,"★ yes",""))
A28: I | B28: Initiative | C28: =IF(Character!$O$3="","",IFERROR(IF(INDEX(Data_Careers!$T:$T,MATCH(Character!$O$3&"|1",Data_Careers!$A:$A,0))="","",INDEX(Data_Careers!$T:$T,MATCH(Character!$O$3&"|1",Data_Careers!$A:$A,0))),"")) | D28: =IF(C28="","",IF(N(C28)<=$D$3,"★ yes",""))
A29: Ag | B29: Agility | C29: =IF(Character!$O$3="","",IFERROR(IF(INDEX(Data_Careers!$U:$U,MATCH(Character!$O$3&"|1",Data_Careers!$A:$A,0))="","",INDEX(Data_Careers!$U:$U,MATCH(Character!$O$3&"|1",Data_Careers!$A:$A,0))),"")) | D29: =IF(C29="","",IF(N(C29)<=$D$3,"★ yes",""))
A30: Dex | B30: Dexterity | C30: =IF(Character!$O$3="","",IFERROR(IF(INDEX(Data_Careers!$V:$V,MATCH(Character!$O$3&"|1",Data_Careers!$A:$A,0))="","",INDEX(Data_Careers!$V:$V,MATCH(Character!$O$3&"|1",Data_Careers!$A:$A,0))),"")) | D30: =IF(C30="","",IF(N(C30)<=$D$3,"★ yes",""))
A31: Int | B31: Intelligence | C31: =IF(Character!$O$3="","",IFERROR(IF(INDEX(Data_Careers!$W:$W,MATCH(Character!$O$3&"|1",Data_Careers!$A:$A,0))="","",INDEX(Data_Careers!$W:$W,MATCH(Character!$O$3&"|1",Data_Careers!$A:$A,0))),"")) | D31: =IF(C31="","",IF(N(C31)<=$D$3,"★ yes",""))
A32: WP | B32: Willpower | C32: =IF(Character!$O$3="","",IFERROR(IF(INDEX(Data_Careers!$X:$X,MATCH(Character!$O$3&"|1",Data_Careers!$A:$A,0))="","",INDEX(Data_Careers!$X:$X,MATCH(Character!$O$3&"|1",Data_Careers!$A:$A,0))),"")) | D32: =IF(C32="","",IF(N(C32)<=$D$3,"★ yes",""))
A33: Fel | B33: Fellowship | C33: =IF(Character!$O$3="","",IFERROR(IF(INDEX(Data_Careers!$Y:$Y,MATCH(Character!$O$3&"|1",Data_Careers!$A:$A,0))="","",INDEX(Data_Careers!$Y:$Y,MATCH(Character!$O$3&"|1",Data_Careers!$A:$A,0))),"")) | D33: =IF(C33="","",IF(N(C33)<=$D$3,"★ yes",""))

Sheet Equipment
A1: EQUIPMENT
A2: Pick items from the dropdowns; stats fill in automatically. Worn items count 1 Enc less. Items inside a container count towards that container's capacity, not your own (only the container's Enc does).
A4: WEAPONS
A5: Weapon | B5: Group | C5: Hands | D5: Reach / Range | E5: Damage | F5: Damage total | G5: Qualities & Flaws | H5: Enc | I5: Location | J5: Skill value | K5: Price | L5: Notes
B6: =IF(A6="","",IFERROR(INDEX(Data_Gear!$C:$C,MATCH(A6,Data_Gear!$A:$A,0))&"","")) | C6: =IF(A6="","",IFERROR(INDEX(Data_Gear!$D:$D,MATCH(A6,Data_Gear!$A:$A,0))&"","")) | D6: =IF(A6="","",IFERROR(INDEX(Data_Gear!$J:$J,MATCH(A6,Data_Gear!$A:$A,0))&"","")) | E6: =IF(A6="","",IFERROR(INDEX(Data_Gear!$K:$K,MATCH(A6,Data_Gear!$A:$A,0))&"","")) | F6: =IF(E6="","",IFERROR(IF(ISNUMBER(SEARCH("SB",E6)),Character!$D$17,0)+VALUE(SUBSTITUTE(SUBSTITUTE(SUBSTITUTE(SUBSTITUTE(SUBSTITUTE(E6,"+SB",""),"SB","")," ",""),"+",""),"–","-")),IF(ISNUMBER(SEARCH("SB",E6)),Character!$D$17,""))) | G6: =IF(A6="","",IFERROR(INDEX(Data_Gear!$L:$L,MATCH(A6,Data_Gear!$A:$A,0))&"","")) | H6: =IF(A6="","",IFERROR(INDEX(Data_Gear!$G:$G,MATCH(A6,Data_Gear!$A:$A,0)),"")) | J6: =IF(A6="","",IFERROR(INDEX(Character!$G$27:$G$77,MATCH(IF(M6="Melee weapon","Melee (","Ranged (")&B6&")",Character!$A$27:$A$77,0)),IF(M6="Melee weapon",Character!$B$16,Character!$C$16))) | K6: =IF(A6="","",IFERROR(INDEX(Data_Gear!$E:$E,MATCH(A6,Data_Gear!$A:$A,0))&"","")) | M6: =IF(A6="","",IFERROR(INDEX(Data_Gear!$B:$B,MATCH(A6,Data_Gear!$A:$A,0))&"","")) | N6: =IF(A6="",0,MAX(0,N(H6)-IF(I6="Worn",1,0)))
B7: =IF(A7="","",IFERROR(INDEX(Data_Gear!$C:$C,MATCH(A7,Data_Gear!$A:$A,0))&"","")) | C7: =IF(A7="","",IFERROR(INDEX(Data_Gear!$D:$D,MATCH(A7,Data_Gear!$A:$A,0))&"","")) | D7: =IF(A7="","",IFERROR(INDEX(Data_Gear!$J:$J,MATCH(A7,Data_Gear!$A:$A,0))&"","")) | E7: =IF(A7="","",IFERROR(INDEX(Data_Gear!$K:$K,MATCH(A7,Data_Gear!$A:$A,0))&"","")) | F7: =IF(E7="","",IFERROR(IF(ISNUMBER(SEARCH("SB",E7)),Character!$D$17,0)+VALUE(SUBSTITUTE(SUBSTITUTE(SUBSTITUTE(SUBSTITUTE(SUBSTITUTE(E7,"+SB",""),"SB","")," ",""),"+",""),"–","-")),IF(ISNUMBER(SEARCH("SB",E7)),Character!$D$17,""))) | G7: =IF(A7="","",IFERROR(INDEX(Data_Gear!$L:$L,MATCH(A7,Data_Gear!$A:$A,0))&"","")) | H7: =IF(A7="","",IFERROR(INDEX(Data_Gear!$G:$G,MATCH(A7,Data_Gear!$A:$A,0)),"")) | J7: =IF(A7="","",IFERROR(INDEX(Character!$G$27:$G$77,MATCH(IF(M7="Melee weapon","Melee (","Ranged (")&B7&")",Character!$A$27:$A$77,0)),IF(M7="Melee weapon",Character!$B$16,Character!$C$16))) | K7: =IF(A7="","",IFERROR(INDEX(Data_Gear!$E:$E,MATCH(A7,Data_Gear!$A:$A,0))&"","")) | M7: =IF(A7="","",IFERROR(INDEX(Data_Gear!$B:$B,MATCH(A7,Data_Gear!$A:$A,0))&"","")) | N7: =IF(A7="",0,MAX(0,N(H7)-IF(I7="Worn",1,0)))
B8: =IF(A8="","",IFERROR(INDEX(Data_Gear!$C:$C,MATCH(A8,Data_Gear!$A:$A,0))&"","")) | C8: =IF(A8="","",IFERROR(INDEX(Data_Gear!$D:$D,MATCH(A8,Data_Gear!$A:$A,0))&"","")) | D8: =IF(A8="","",IFERROR(INDEX(Data_Gear!$J:$J,MATCH(A8,Data_Gear!$A:$A,0))&"","")) | E8: =IF(A8="","",IFERROR(INDEX(Data_Gear!$K:$K,MATCH(A8,Data_Gear!$A:$A,0))&"","")) | F8: =IF(E8="","",IFERROR(IF(ISNUMBER(SEARCH("SB",E8)),Character!$D$17,0)+VALUE(SUBSTITUTE(SUBSTITUTE(SUBSTITUTE(SUBSTITUTE(SUBSTITUTE(E8,"+SB",""),"SB","")," ",""),"+",""),"–","-")),IF(ISNUMBER(SEARCH("SB",E8)),Character!$D$17,""))) | G8: =IF(A8="","",IFERROR(INDEX(Data_Gear!$L:$L,MATCH(A8,Data_Gear!$A:$A,0))&"","")) | H8: =IF(A8="","",IFERROR(INDEX(Data_Gear!$G:$G,MATCH(A8,Data_Gear!$A:$A,0)),"")) | J8: =IF(A8="","",IFERROR(INDEX(Character!$G$27:$G$77,MATCH(IF(M8="Melee weapon","Melee (","Ranged (")&B8&")",Character!$A$27:$A$77,0)),IF(M8="Melee weapon",Character!$B$16,Character!$C$16))) | K8: =IF(A8="","",IFERROR(INDEX(Data_Gear!$E:$E,MATCH(A8,Data_Gear!$A:$A,0))&"","")) | M8: =IF(A8="","",IFERROR(INDEX(Data_Gear!$B:$B,MATCH(A8,Data_Gear!$A:$A,0))&"","")) | N8: =IF(A8="",0,MAX(0,N(H8)-IF(I8="Worn",1,0)))
B9: =IF(A9="","",IFERROR(INDEX(Data_Gear!$C:$C,MATCH(A9,Data_Gear!$A:$A,0))&"","")) | C9: =IF(A9="","",IFERROR(INDEX(Data_Gear!$D:$D,MATCH(A9,Data_Gear!$A:$A,0))&"","")) | D9: =IF(A9="","",IFERROR(INDEX(Data_Gear!$J:$J,MATCH(A9,Data_Gear!$A:$A,0))&"","")) | E9: =IF(A9="","",IFERROR(INDEX(Data_Gear!$K:$K,MATCH(A9,Data_Gear!$A:$A,0))&"","")) | F9: =IF(E9="","",IFERROR(IF(ISNUMBER(SEARCH("SB",E9)),Character!$D$17,0)+VALUE(SUBSTITUTE(SUBSTITUTE(SUBSTITUTE(SUBSTITUTE(SUBSTITUTE(E9,"+SB",""),"SB","")," ",""),"+",""),"–","-")),IF(ISNUMBER(SEARCH("SB",E9)),Character!$D$17,""))) | G9: =IF(A9="","",IFERROR(INDEX(Data_Gear!$L:$L,MATCH(A9,Data_Gear!$A:$A,0))&"","")) | H9: =IF(A9="","",IFERROR(INDEX(Data_Gear!$G:$G,MATCH(A9,Data_Gear!$A:$A,0)),"")) | J9: =IF(A9="","",IFERROR(INDEX(Character!$G$27:$G$77,MATCH(IF(M9="Melee weapon","Melee (","Ranged (")&B9&")",Character!$A$27:$A$77,0)),IF(M9="Melee weapon",Character!$B$16,Character!$C$16))) | K9: =IF(A9="","",IFERROR(INDEX(Data_Gear!$E:$E,MATCH(A9,Data_Gear!$A:$A,0))&"","")) | M9: =IF(A9="","",IFERROR(INDEX(Data_Gear!$B:$B,MATCH(A9,Data_Gear!$A:$A,0))&"","")) | N9: =IF(A9="",0,MAX(0,N(H9)-IF(I9="Worn",1,0)))
B10: =IF(A10="","",IFERROR(INDEX(Data_Gear!$C:$C,MATCH(A10,Data_Gear!$A:$A,0))&"","")) | C10: =IF(A10="","",IFERROR(INDEX(Data_Gear!$D:$D,MATCH(A10,Data_Gear!$A:$A,0))&"","")) | D10: =IF(A10="","",IFERROR(INDEX(Data_Gear!$J:$J,MATCH(A10,Data_Gear!$A:$A,0))&"","")) | E10: =IF(A10="","",IFERROR(INDEX(Data_Gear!$K:$K,MATCH(A10,Data_Gear!$A:$A,0))&"","")) | F10: =IF(E10="","",IFERROR(IF(ISNUMBER(SEARCH("SB",E10)),Character!$D$17,0)+VALUE(SUBSTITUTE(SUBSTITUTE(SUBSTITUTE(SUBSTITUTE(SUBSTITUTE(E10,"+SB",""),"SB","")," ",""),"+",""),"–","-")),IF(ISNUMBER(SEARCH("SB",E10)),Character!$D$17,""))) | G10: =IF(A10="","",IFERROR(INDEX(Data_Gear!$L:$L,MATCH(A10,Data_Gear!$A:$A,0))&"","")) | H10: =IF(A10="","",IFERROR(INDEX(Data_Gear!$G:$G,MATCH(A10,Data_Gear!$A:$A,0)),"")) | J10: =IF(A10="","",IFERROR(INDEX(Character!$G$27:$G$77,MATCH(IF(M10="Melee weapon","Melee (","Ranged (")&B10&")",Character!$A$27:$A$77,0)),IF(M10="Melee weapon",Character!$B$16,Character!$C$16))) | K10: =IF(A10="","",IFERROR(INDEX(Data_Gear!$E:$E,MATCH(A10,Data_Gear!$A:$A,0))&"","")) | M10: =IF(A10="","",IFERROR(INDEX(Data_Gear!$B:$B,MATCH(A10,Data_Gear!$A:$A,0))&"","")) | N10: =IF(A10="",0,MAX(0,N(H10)-IF(I10="Worn",1,0)))
B11: =IF(A11="","",IFERROR(INDEX(Data_Gear!$C:$C,MATCH(A11,Data_Gear!$A:$A,0))&"","")) | C11: =IF(A11="","",IFERROR(INDEX(Data_Gear!$D:$D,MATCH(A11,Data_Gear!$A:$A,0))&"","")) | D11: =IF(A11="","",IFERROR(INDEX(Data_Gear!$J:$J,MATCH(A11,Data_Gear!$A:$A,0))&"","")) | E11: =IF(A11="","",IFERROR(INDEX(Data_Gear!$K:$K,MATCH(A11,Data_Gear!$A:$A,0))&"","")) | F11: =IF(E11="","",IFERROR(IF(ISNUMBER(SEARCH("SB",E11)),Character!$D$17,0)+VALUE(SUBSTITUTE(SUBSTITUTE(SUBSTITUTE(SUBSTITUTE(SUBSTITUTE(E11,"+SB",""),"SB","")," ",""),"+",""),"–","-")),IF(ISNUMBER(SEARCH("SB",E11)),Character!$D$17,""))) | G11: =IF(A11="","",IFERROR(INDEX(Data_Gear!$L:$L,MATCH(A11,Data_Gear!$A:$A,0))&"","")) | H11: =IF(A11="","",IFERROR(INDEX(Data_Gear!$G:$G,MATCH(A11,Data_Gear!$A:$A,0)),"")) | J11: =IF(A11="","",IFERROR(INDEX(Character!$G$27:$G$77,MATCH(IF(M11="Melee weapon","Melee (","Ranged (")&B11&")",Character!$A$27:$A$77,0)),IF(M11="Melee weapon",Character!$B$16,Character!$C$16))) | K11: =IF(A11="","",IFERROR(INDEX(Data_Gear!$E:$E,MATCH(A11,Data_Gear!$A:$A,0))&"","")) | M11: =IF(A11="","",IFERROR(INDEX(Data_Gear!$B:$B,MATCH(A11,Data_Gear!$A:$A,0))&"","")) | N11: =IF(A11="",0,MAX(0,N(H11)-IF(I11="Worn",1,0)))
B12: =IF(A12="","",IFERROR(INDEX(Data_Gear!$C:$C,MATCH(A12,Data_Gear!$A:$A,0))&"","")) | C12: =IF(A12="","",IFERROR(INDEX(Data_Gear!$D:$D,MATCH(A12,Data_Gear!$A:$A,0))&"","")) | D12: =IF(A12="","",IFERROR(INDEX(Data_Gear!$J:$J,MATCH(A12,Data_Gear!$A:$A,0))&"","")) | E12: =IF(A12="","",IFERROR(INDEX(Data_Gear!$K:$K,MATCH(A12,Data_Gear!$A:$A,0))&"","")) | F12: =IF(E12="","",IFERROR(IF(ISNUMBER(SEARCH("SB",E12)),Character!$D$17,0)+VALUE(SUBSTITUTE(SUBSTITUTE(SUBSTITUTE(SUBSTITUTE(SUBSTITUTE(E12,"+SB",""),"SB","")," ",""),"+",""),"–","-")),IF(ISNUMBER(SEARCH("SB",E12)),Character!$D$17,""))) | G12: =IF(A12="","",IFERROR(INDEX(Data_Gear!$L:$L,MATCH(A12,Data_Gear!$A:$A,0))&"","")) | H12: =IF(A12="","",IFERROR(INDEX(Data_Gear!$G:$G,MATCH(A12,Data_Gear!$A:$A,0)),"")) | J12: =IF(A12="","",IFERROR(INDEX(Character!$G$27:$G$77,MATCH(IF(M12="Melee weapon","Melee (","Ranged (")&B12&")",Character!$A$27:$A$77,0)),IF(M12="Melee weapon",Character!$B$16,Character!$C$16))) | K12: =IF(A12="","",IFERROR(INDEX(Data_Gear!$E:$E,MATCH(A12,Data_Gear!$A:$A,0))&"","")) | M12: =IF(A12="","",IFERROR(INDEX(Data_Gear!$B:$B,MATCH(A12,Data_Gear!$A:$A,0))&"","")) | N12: =IF(A12="",0,MAX(0,N(H12)-IF(I12="Worn",1,0)))
B13: =IF(A13="","",IFERROR(INDEX(Data_Gear!$C:$C,MATCH(A13,Data_Gear!$A:$A,0))&"","")) | C13: =IF(A13="","",IFERROR(INDEX(Data_Gear!$D:$D,MATCH(A13,Data_Gear!$A:$A,0))&"","")) | D13: =IF(A13="","",IFERROR(INDEX(Data_Gear!$J:$J,MATCH(A13,Data_Gear!$A:$A,0))&"","")) | E13: =IF(A13="","",IFERROR(INDEX(Data_Gear!$K:$K,MATCH(A13,Data_Gear!$A:$A,0))&"","")) | F13: =IF(E13="","",IFERROR(IF(ISNUMBER(SEARCH("SB",E13)),Character!$D$17,0)+VALUE(SUBSTITUTE(SUBSTITUTE(SUBSTITUTE(SUBSTITUTE(SUBSTITUTE(E13,"+SB",""),"SB","")," ",""),"+",""),"–","-")),IF(ISNUMBER(SEARCH("SB",E13)),Character!$D$17,""))) | G13: =IF(A13="","",IFERROR(INDEX(Data_Gear!$L:$L,MATCH(A13,Data_Gear!$A:$A,0))&"","")) | H13: =IF(A13="","",IFERROR(INDEX(Data_Gear!$G:$G,MATCH(A13,Data_Gear!$A:$A,0)),"")) | J13: =IF(A13="","",IFERROR(INDEX(Character!$G$27:$G$77,MATCH(IF(M13="Melee weapon","Melee (","Ranged (")&B13&")",Character!$A$27:$A$77,0)),IF(M13="Melee weapon",Character!$B$16,Character!$C$16))) | K13: =IF(A13="","",IFERROR(INDEX(Data_Gear!$E:$E,MATCH(A13,Data_Gear!$A:$A,0))&"","")) | M13: =IF(A13="","",IFERROR(INDEX(Data_Gear!$B:$B,MATCH(A13,Data_Gear!$A:$A,0))&"","")) | N13: =IF(A13="",0,MAX(0,N(H13)-IF(I13="Worn",1,0)))
A15: ARMOUR & SHIELDS
A16: Armour | B16: Locations | C16: AP | D16: Penalty | G16: Qualities & Flaws | H16: Enc | I16: Location | J16: Notes
B17: =IF(A17="","",IFERROR(INDEX(Data_Gear!$M:$M,MATCH(A17,Data_Gear!$A:$A,0))&"","")) | C17: =IF(A17="",0,IFERROR(N(INDEX(Data_Gear!$N:$N,MATCH(A17,Data_Gear!$A:$A,0))),0)) | D17: =IF(A17="","",IFERROR(INDEX(Data_Gear!$O:$O,MATCH(A17,Data_Gear!$A:$A,0))&"","")) | G17: =IF(A17="","",IFERROR(INDEX(Data_Gear!$L:$L,MATCH(A17,Data_Gear!$A:$A,0))&"","")) | H17: =IF(A17="","",IFERROR(INDEX(Data_Gear!$G:$G,MATCH(A17,Data_Gear!$A:$A,0)),"")) | N17: =IF(A17="",0,MAX(0,N(H17)-IF(I17="Worn",1,0)))
B18: =IF(A18="","",IFERROR(INDEX(Data_Gear!$M:$M,MATCH(A18,Data_Gear!$A:$A,0))&"","")) | C18: =IF(A18="",0,IFERROR(N(INDEX(Data_Gear!$N:$N,MATCH(A18,Data_Gear!$A:$A,0))),0)) | D18: =IF(A18="","",IFERROR(INDEX(Data_Gear!$O:$O,MATCH(A18,Data_Gear!$A:$A,0))&"","")) | G18: =IF(A18="","",IFERROR(INDEX(Data_Gear!$L:$L,MATCH(A18,Data_Gear!$A:$A,0))&"","")) | H18: =IF(A18="","",IFERROR(INDEX(Data_Gear!$G:$G,MATCH(A18,Data_Gear!$A:$A,0)),"")) | N18: =IF(A18="",0,MAX(0,N(H18)-IF(I18="Worn",1,0)))
B19: =IF(A19="","",IFERROR(INDEX(Data_Gear!$M:$M,MATCH(A19,Data_Gear!$A:$A,0))&"","")) | C19: =IF(A19="",0,IFERROR(N(INDEX(Data_Gear!$N:$N,MATCH(A19,Data_Gear!$A:$A,0))),0)) | D19: =IF(A19="","",IFERROR(INDEX(Data_Gear!$O:$O,MATCH(A19,Data_Gear!$A:$A,0))&"","")) | G19: =IF(A19="","",IFERROR(INDEX(Data_Gear!$L:$L,MATCH(A19,Data_Gear!$A:$A,0))&"","")) | H19: =IF(A19="","",IFERROR(INDEX(Data_Gear!$G:$G,MATCH(A19,Data_Gear!$A:$A,0)),"")) | N19: =IF(A19="",0,MAX(0,N(H19)-IF(I19="Worn",1,0)))
B20: =IF(A20="","",IFERROR(INDEX(Data_Gear!$M:$M,MATCH(A20,Data_Gear!$A:$A,0))&"","")) | C20: =IF(A20="",0,IFERROR(N(INDEX(Data_Gear!$N:$N,MATCH(A20,Data_Gear!$A:$A,0))),0)) | D20: =IF(A20="","",IFERROR(INDEX(Data_Gear!$O:$O,MATCH(A20,Data_Gear!$A:$A,0))&"","")) | G20: =IF(A20="","",IFERROR(INDEX(Data_Gear!$L:$L,MATCH(A20,Data_Gear!$A:$A,0))&"","")) | H20: =IF(A20="","",IFERROR(INDEX(Data_Gear!$G:$G,MATCH(A20,Data_Gear!$A:$A,0)),"")) | N20: =IF(A20="",0,MAX(0,N(H20)-IF(I20="Worn",1,0)))
B21: =IF(A21="","",IFERROR(INDEX(Data_Gear!$M:$M,MATCH(A21,Data_Gear!$A:$A,0))&"","")) | C21: =IF(A21="",0,IFERROR(N(INDEX(Data_Gear!$N:$N,MATCH(A21,Data_Gear!$A:$A,0))),0)) | D21: =IF(A21="","",IFERROR(INDEX(Data_Gear!$O:$O,MATCH(A21,Data_Gear!$A:$A,0))&"","")) | G21: =IF(A21="","",IFERROR(INDEX(Data_Gear!$L:$L,MATCH(A21,Data_Gear!$A:$A,0))&"","")) | H21: =IF(A21="","",IFERROR(INDEX(Data_Gear!$G:$G,MATCH(A21,Data_Gear!$A:$A,0)),"")) | N21: =IF(A21="",0,MAX(0,N(H21)-IF(I21="Worn",1,0)))
B22: =IF(A22="","",IFERROR(INDEX(Data_Gear!$M:$M,MATCH(A22,Data_Gear!$A:$A,0))&"","")) | C22: =IF(A22="",0,IFERROR(N(INDEX(Data_Gear!$N:$N,MATCH(A22,Data_Gear!$A:$A,0))),0)) | D22: =IF(A22="","",IFERROR(INDEX(Data_Gear!$O:$O,MATCH(A22,Data_Gear!$A:$A,0))&"","")) | G22: =IF(A22="","",IFERROR(INDEX(Data_Gear!$L:$L,MATCH(A22,Data_Gear!$A:$A,0))&"","")) | H22: =IF(A22="","",IFERROR(INDEX(Data_Gear!$G:$G,MATCH(A22,Data_Gear!$A:$A,0)),"")) | N22: =IF(A22="",0,MAX(0,N(H22)-IF(I22="Worn",1,0)))
B23: =IF(A23="","",IFERROR(INDEX(Data_Gear!$M:$M,MATCH(A23,Data_Gear!$A:$A,0))&"","")) | C23: =IF(A23="",0,IFERROR(N(INDEX(Data_Gear!$N:$N,MATCH(A23,Data_Gear!$A:$A,0))),0)) | D23: =IF(A23="","",IFERROR(INDEX(Data_Gear!$O:$O,MATCH(A23,Data_Gear!$A:$A,0))&"","")) | G23: =IF(A23="","",IFERROR(INDEX(Data_Gear!$L:$L,MATCH(A23,Data_Gear!$A:$A,0))&"","")) | H23: =IF(A23="","",IFERROR(INDEX(Data_Gear!$G:$G,MATCH(A23,Data_Gear!$A:$A,0)),"")) | N23: =IF(A23="",0,MAX(0,N(H23)-IF(I23="Worn",1,0)))
B24: =IF(A24="","",IFERROR(INDEX(Data_Gear!$M:$M,MATCH(A24,Data_Gear!$A:$A,0))&"","")) | C24: =IF(A24="",0,IFERROR(N(INDEX(Data_Gear!$N:$N,MATCH(A24,Data_Gear!$A:$A,0))),0)) | D24: =IF(A24="","",IFERROR(INDEX(Data_Gear!$O:$O,MATCH(A24,Data_Gear!$A:$A,0))&"","")) | G24: =IF(A24="","",IFERROR(INDEX(Data_Gear!$L:$L,MATCH(A24,Data_Gear!$A:$A,0))&"","")) | H24: =IF(A24="","",IFERROR(INDEX(Data_Gear!$G:$G,MATCH(A24,Data_Gear!$A:$A,0)),"")) | N24: =IF(A24="",0,MAX(0,N(H24)-IF(I24="Worn",1,0)))
A25: Armour Points (worn) | B25: Head | C25: Arms | D25: Body | E25: Legs | F25: Shield
A26: AP by hit location | B26: =SUMPRODUCT(ISNUMBER(SEARCH("Head",$B$17:$B$24))*($I$17:$I$24="Worn")*$C$17:$C$24) | C26: =SUMPRODUCT(ISNUMBER(SEARCH("Arms",$B$17:$B$24))*($I$17:$I$24="Worn")*$C$17:$C$24) | D26: =SUMPRODUCT(ISNUMBER(SEARCH("Body",$B$17:$B$24))*($I$17:$I$24="Worn")*$C$17:$C$24) | E26: =SUMPRODUCT(ISNUMBER(SEARCH("Legs",$B$17:$B$24))*($I$17:$I$24="Worn")*$C$17:$C$24) | F26: =SUMPRODUCT(($B$17:$B$24="Shield")*(($I$17:$I$24="Worn")+($I$17:$I$24="Carried"))*$C$17:$C$24)
A29: TRAPPINGS
A30: Item | B30: Qty | C30: Category | D30: Enc (each) | E30: Enc (total) | F30: Location | G30: Availability | H30: Price | I30: Value (pennies) | J30: Notes
C31: =IF(A31="","",IFERROR(INDEX(Data_Gear!$B:$B,MATCH(A31,Data_Gear!$A:$A,0))&"","")) | D31: =IF(A31="","",IFERROR(N(INDEX(Data_Gear!$G:$G,MATCH(A31,Data_Gear!$A:$A,0))),0)) | E31: =IF(A31="",0,MAX(0,IF(N(B31)=0,1,N(B31))*N(D31)-IF(F31="Worn",IF(N(B31)=0,1,N(B31)),0))) | G31: =IF(A31="","",IFERROR(INDEX(Data_Gear!$H:$H,MATCH(A31,Data_Gear!$A:$A,0))&"","")) | H31: =IF(A31="","",IFERROR(INDEX(Data_Gear!$E:$E,MATCH(A31,Data_Gear!$A:$A,0))&"","")) | I31: =IF(A31="","",IFERROR(IF(N(B31)=0,1,N(B31))*INDEX(Data_Gear!$F:$F,MATCH(A31,Data_Gear!$A:$A,0)),""))
C32: =IF(A32="","",IFERROR(INDEX(Data_Gear!$B:$B,MATCH(A32,Data_Gear!$A:$A,0))&"","")) | D32: =IF(A32="","",IFERROR(N(INDEX(Data_Gear!$G:$G,MATCH(A32,Data_Gear!$A:$A,0))),0)) | E32: =IF(A32="",0,MAX(0,IF(N(B32)=0,1,N(B32))*N(D32)-IF(F32="Worn",IF(N(B32)=0,1,N(B32)),0))) | G32: =IF(A32="","",IFERROR(INDEX(Data_Gear!$H:$H,MATCH(A32,Data_Gear!$A:$A,0))&"","")) | H32: =IF(A32="","",IFERROR(INDEX(Data_Gear!$E:$E,MATCH(A32,Data_Gear!$A:$A,0))&"","")) | I32: =IF(A32="","",IFERROR(IF(N(B32)=0,1,N(B32))*INDEX(Data_Gear!$F:$F,MATCH(A32,Data_Gear!$A:$A,0)),""))
C33: =IF(A33="","",IFERROR(INDEX(Data_Gear!$B:$B,MATCH(A33,Data_Gear!$A:$A,0))&"","")) | D33: =IF(A33="","",IFERROR(N(INDEX(Data_Gear!$G:$G,MATCH(A33,Data_Gear!$A:$A,0))),0)) | E33: =IF(A33="",0,MAX(0,IF(N(B33)=0,1,N(B33))*N(D33)-IF(F33="Worn",IF(N(B33)=0,1,N(B33)),0))) | G33: =IF(A33="","",IFERROR(INDEX(Data_Gear!$H:$H,MATCH(A33,Data_Gear!$A:$A,0))&"","")) | H33: =IF(A33="","",IFERROR(INDEX(Data_Gear!$E:$E,MATCH(A33,Data_Gear!$A:$A,0))&"","")) | I33: =IF(A33="","",IFERROR(IF(N(B33)=0,1,N(B33))*INDEX(Data_Gear!$F:$F,MATCH(A33,Data_Gear!$A:$A,0)),""))
C34: =IF(A34="","",IFERROR(INDEX(Data_Gear!$B:$B,MATCH(A34,Data_Gear!$A:$A,0))&"","")) | D34: =IF(A34="","",IFERROR(N(INDEX(Data_Gear!$G:$G,MATCH(A34,Data_Gear!$A:$A,0))),0)) | E34: =IF(A34="",0,MAX(0,IF(N(B34)=0,1,N(B34))*N(D34)-IF(F34="Worn",IF(N(B34)=0,1,N(B34)),0))) | G34: =IF(A34="","",IFERROR(INDEX(Data_Gear!$H:$H,MATCH(A34,Data_Gear!$A:$A,0))&"","")) | H34: =IF(A34="","",IFERROR(INDEX(Data_Gear!$E:$E,MATCH(A34,Data_Gear!$A:$A,0))&"","")) | I34: =IF(A34="","",IFERROR(IF(N(B34)=0,1,N(B34))*INDEX(Data_Gear!$F:$F,MATCH(A34,Data_Gear!$A:$A,0)),""))
C35: =IF(A35="","",IFERROR(INDEX(Data_Gear!$B:$B,MATCH(A35,Data_Gear!$A:$A,0))&"","")) | D35: =IF(A35="","",IFERROR(N(INDEX(Data_Gear!$G:$G,MATCH(A35,Data_Gear!$A:$A,0))),0)) | E35: =IF(A35="",0,MAX(0,IF(N(B35)=0,1,N(B35))*N(D35)-IF(F35="Worn",IF(N(B35)=0,1,N(B35)),0))) | G35: =IF(A35="","",IFERROR(INDEX(Data_Gear!$H:$H,MATCH(A35,Data_Gear!$A:$A,0))&"","")) | H35: =IF(A35="","",IFERROR(INDEX(Data_Gear!$E:$E,MATCH(A35,Data_Gear!$A:$A,0))&"","")) | I35: =IF(A35="","",IFERROR(IF(N(B35)=0,1,N(B35))*INDEX(Data_Gear!$F:$F,MATCH(A35,Data_Gear!$A:$A,0)),""))
C36: =IF(A36="","",IFERROR(INDEX(Data_Gear!$B:$B,MATCH(A36,Data_Gear!$A:$A,0))&"","")) | D36: =IF(A36="","",IFERROR(N(INDEX(Data_Gear!$G:$G,MATCH(A36,Data_Gear!$A:$A,0))),0)) | E36: =IF(A36="",0,MAX(0,IF(N(B36)=0,1,N(B36))*N(D36)-IF(F36="Worn",IF(N(B36)=0,1,N(B36)),0))) | G36: =IF(A36="","",IFERROR(INDEX(Data_Gear!$H:$H,MATCH(A36,Data_Gear!$A:$A,0))&"","")) | H36: =IF(A36="","",IFERROR(INDEX(Data_Gear!$E:$E,MATCH(A36,Data_Gear!$A:$A,0))&"","")) | I36: =IF(A36="","",IFERROR(IF(N(B36)=0,1,N(B36))*INDEX(Data_Gear!$F:$F,MATCH(A36,Data_Gear!$A:$A,0)),""))
C37: =IF(A37="","",IFERROR(INDEX(Data_Gear!$B:$B,MATCH(A37,Data_Gear!$A:$A,0))&"","")) | D37: =IF(A37="","",IFERROR(N(INDEX(Data_Gear!$G:$G,MATCH(A37,Data_Gear!$A:$A,0))),0)) | E37: =IF(A37="",0,MAX(0,IF(N(B37)=0,1,N(B37))*N(D37)-IF(F37="Worn",IF(N(B37)=0,1,N(B37)),0))) | G37: =IF(A37="","",IFERROR(INDEX(Data_Gear!$H:$H,MATCH(A37,Data_Gear!$A:$A,0))&"","")) | H37: =IF(A37="","",IFERROR(INDEX(Data_Gear!$E:$E,MATCH(A37,Data_Gear!$A:$A,0))&"","")) | I37: =IF(A37="","",IFERROR(IF(N(B37)=0,1,N(B37))*INDEX(Data_Gear!$F:$F,MATCH(A37,Data_Gear!$A:$A,0)),""))
C38: =IF(A38="","",IFERROR(INDEX(Data_Gear!$B:$B,MATCH(A38,Data_Gear!$A:$A,0))&"","")) | D38: =IF(A38="","",IFERROR(N(INDEX(Data_Gear!$G:$G,MATCH(A38,Data_Gear!$A:$A,0))),0)) | E38: =IF(A38="",0,MAX(0,IF(N(B38)=0,1,N(B38))*N(D38)-IF(F38="Worn",IF(N(B38)=0,1,N(B38)),0))) | G38: =IF(A38="","",IFERROR(INDEX(Data_Gear!$H:$H,MATCH(A38,Data_Gear!$A:$A,0))&"","")) | H38: =IF(A38="","",IFERROR(INDEX(Data_Gear!$E:$E,MATCH(A38,Data_Gear!$A:$A,0))&"","")) | I38: =IF(A38="","",IFERROR(IF(N(B38)=0,1,N(B38))*INDEX(Data_Gear!$F:$F,MATCH(A38,Data_Gear!$A:$A,0)),""))
C39: =IF(A39="","",IFERROR(INDEX(Data_Gear!$B:$B,MATCH(A39,Data_Gear!$A:$A,0))&"","")) | D39: =IF(A39="","",IFERROR(N(INDEX(Data_Gear!$G:$G,MATCH(A39,Data_Gear!$A:$A,0))),0)) | E39: =IF(A39="",0,MAX(0,IF(N(B39)=0,1,N(B39))*N(D39)-IF(F39="Worn",IF(N(B39)=0,1,N(B39)),0))) | G39: =IF(A39="","",IFERROR(INDEX(Data_Gear!$H:$H,MATCH(A39,Data_Gear!$A:$A,0))&"","")) | H39: =IF(A39="","",IFERROR(INDEX(Data_Gear!$E:$E,MATCH(A39,Data_Gear!$A:$A,0))&"","")) | I39: =IF(A39="","",IFERROR(IF(N(B39)=0,1,N(B39))*INDEX(Data_Gear!$F:$F,MATCH(A39,Data_Gear!$A:$A,0)),""))
C40: =IF(A40="","",IFERROR(INDEX(Data_Gear!$B:$B,MATCH(A40,Data_Gear!$A:$A,0))&"","")) | D40: =IF(A40="","",IFERROR(N(INDEX(Data_Gear!$G:$G,MATCH(A40,Data_Gear!$A:$A,0))),0)) | E40: =IF(A40="",0,MAX(0,IF(N(B40)=0,1,N(B40))*N(D40)-IF(F40="Worn",IF(N(B40)=0,1,N(B40)),0))) | G40: =IF(A40="","",IFERROR(INDEX(Data_Gear!$H:$H,MATCH(A40,Data_Gear!$A:$A,0))&"","")) | H40: =IF(A40="","",IFERROR(INDEX(Data_Gear!$E:$E,MATCH(A40,Data_Gear!$A:$A,0))&"","")) | I40: =IF(A40="","",IFERROR(IF(N(B40)=0,1,N(B40))*INDEX(Data_Gear!$F:$F,MATCH(A40,Data_Gear!$A:$A,0)),""))
C41: =IF(A41="","",IFERROR(INDEX(Data_Gear!$B:$B,MATCH(A41,Data_Gear!$A:$A,0))&"","")) | D41: =IF(A41="","",IFERROR(N(INDEX(Data_Gear!$G:$G,MATCH(A41,Data_Gear!$A:$A,0))),0)) | E41: =IF(A41="",0,MAX(0,IF(N(B41)=0,1,N(B41))*N(D41)-IF(F41="Worn",IF(N(B41)=0,1,N(B41)),0))) | G41: =IF(A41="","",IFERROR(INDEX(Data_Gear!$H:$H,MATCH(A41,Data_Gear!$A:$A,0))&"","")) | H41: =IF(A41="","",IFERROR(INDEX(Data_Gear!$E:$E,MATCH(A41,Data_Gear!$A:$A,0))&"","")) | I41: =IF(A41="","",IFERROR(IF(N(B41)=0,1,N(B41))*INDEX(Data_Gear!$F:$F,MATCH(A41,Data_Gear!$A:$A,0)),""))
